Workbook
Name Mongeral_TM_10: "Teste"
Name Produtos: #N/A
Name Teste2: #N/A

Sheet Simulador
A1: Inserir dados | I1: Nascimento
A2: Nome | C2: Idade | E2: Capital Segurado | F2: Sexo | G2: IPCA | H2: Period. | I2: 29159
A3: Augusto Giani | B3: DANIEL | C3: 28 | D3: 64 | E3: 150000 | F3: Masculino | G3: 0.055 | H3: Mensal | I3: =TODAY() -> 46127
I4: =INT((I3-I2))/365.25 -> 46.455852
A5: ESTRATÉGIA DE MÉDIO PRAZO
A6: SEGURO RESGATÁVEL | Dinâmica Financeira | F6: =A3 -> Augusto Giani
A7: PROTEÇÃO FAMILIAR + FORMAÇÃO DE RESERVA | J7: Aporte c/ Agravo
A8: =TODAY() -> 46127
A9: * Considerando IPCA de | C9: =G3 -> 0.055 | D9: aa | E9: aa
A10: O valor de resgate apresentado considera que os prêmios (aportes) são pagos em dia e já está capitalizado atuarialmente com base na taxa de juros de 3% ao ano, restando apenas aplicar o índice de atualização monetária referente ao IPCA mensalmente. A capitalização atuarial utilizada nestes cálculos considera fatores tais como probabilidade de morte, idade, sexo, ano de vigência da apólice e capital segurado.
A11: Congelamento de Risco: | C11: =C3 -> 28 | D11: anos | E11: anos
A13: Anos | B13: Capital Segurado | D13: =IF(H3="Anual","Aporte Anual","Aporte Mensal") -> Aporte Mensal | E13: Aporte Anual | F13: Aporte Acumulado | G13: Reserva Acumulada | J13: Morte Acidental | K13: Aporte
A14: =C3+1 -> 29 | B14: =IFERROR(IF(A14="","",$E$3),"") -> 150000 | D14: =IF(H3="Anual",IF(J8=0,IF(F3="Masculino",Simulações!E7,Simulações!G7),J8),IF(J8=0,IF(F3="Masculino",Simulações!E9,Simulações!G9),J8)) -> 469.82357 | E14: =D14*12*0.97352 -> 5488.5917 | F14: =E14 -> 5488.5917 | G14: =IFERROR(IF($F$3="Masculino",B14*(HLOOKUP($C$3,Resgate!$E$1:$BD$87,Resgate!D2,FALSE)),B14*(HLOOKUP($C$3,Resgate!$BF$1:$DE$87,Resgate!D2,FALSE))),"") -> 0 | H14: =G14/F14 -> 0 | J14: 0 | L14: =IF(J14=0,"",IF(OR(J14>1000000,J14<160000,),"CS ñ Permitido",IF(J14>E3,"CS ñ Permitido",IF(H3="Anual",Simulações!K10,Simulações!K12))))
A15: =IF(A14="","",IF(A14+1>100,"",A14+1)) -> 30 | B15: =IFERROR(IF(A15="","",B14)*(1+$G$3),"") -> 158250 | D15: =D14*(1+$G$3) -> 495.66387 | E15: =D15*12*0.97352 -> 5790.4643 | F15: =F14+E15 -> 11279.056 | G15: =IFERROR(IF($F$3="Masculino",B15*(HLOOKUP($C$3,Resgate!$E$1:$BD$87,Resgate!D3,FALSE)),B15*(HLOOKUP($C$3,Resgate!$BF$1:$DE$87,Resgate!D3,FALSE))),"") -> 0 | H15: =G15/F15 -> 0 | J15: Invalidez Acidental
A16: =IF(A15="","",IF(A15+1>100,"",A15+1)) -> 31 | B16: =IFERROR(IF(A16="","",B15)*(1+$G$3),"") -> 166953.75 | D16: =D15*(1+$G$3) -> 522.92538 | E16: =D16*12*0.97352 -> 6108.9398 | F16: =F15+E16 -> 17387.996 | G16: =IFERROR(IF($F$3="Masculino",B16*(HLOOKUP($C$3,Resgate!$E$1:$BD$87,Resgate!D4,FALSE)),B16*(HLOOKUP($C$3,Resgate!$BF$1:$DE$87,Resgate!D4,FALSE))),"") -> 2500.9672 | H16: =G16/F16 -> 0.14383298 | J16: 200000 | K16: =(L16*12)*0.97352 -> #VALUE! | L16: =IF(J16=0,"",IF(OR(J16>1000000,J16<160000,),"CS ñ Permitido",IF(J16>E3,"CS ñ Permitido",IF(H3="Anual",Simulações!Y10,Simulações!Y12)))) -> CS ñ Permitido
A17: =IF(A16="","",IF(A16+1>100,"",A16+1)) -> 32 | B17: =IFERROR(IF(A17="","",B16)*(1+$G$3),"") -> 176136.21 | D17: =D16*(1+$G$3) -> 551.68628 | E17: =D17*12*0.97352 -> 6444.9315 | F17: =F16+E17 -> 23832.927 | G17: =IFERROR(IF($F$3="Masculino",B17*(HLOOKUP($C$3,Resgate!$E$1:$BD$87,Resgate!D5,FALSE)),B17*(HLOOKUP($C$3,Resgate!$BF$1:$DE$87,Resgate!D5,FALSE))),"") -> 6668.5168 | H17: =G17/F17 -> 0.27980267 | J17: Doenças Graves Plus
A18: =IF(A17="","",IF(A17+1>100,"",A17+1)) -> 33 | B18: =IFERROR(IF(A18="","",B17)*(1+$G$3),"") -> 185823.7 | D18: =D17*(1+$G$3) -> 582.02902 | E18: =D18*12*0.97352 -> 6799.4027 | F18: =F17+E18 -> 30632.33 | G18: =IFERROR(IF($F$3="Masculino",B18*(HLOOKUP($C$3,Resgate!$E$1:$BD$87,Resgate!D6,FALSE)),B18*(HLOOKUP($C$3,Resgate!$BF$1:$DE$87,Resgate!D6,FALSE))),"") -> 14353.022 | H18: =G18/F18 -> 0.46855797 | J18: 200000 | K18: =(L18*12)*0.97352 -> #VALUE! | L18: =IF(J18=0,"",IF(OR(J18>1000000,J18<160000),"CS ñ Permitido",IF(H3="Anual",IF(J8=0,IF(F3="Masculino",Simulações!AB7,Simulações!AD7),J8),IF(J8=0,IF(F3="Masculino",Simulações!AB9,Simulações!AD9),J8)))) -> #VALUE!
A19: =IF(A18="","",IF(A18+1>100,"",A18+1)) -> 34 | B19: =IFERROR(IF(A19="","",B18)*(1+$G$3),"") -> 196044 | D19: =D18*(1+$G$3) -> 614.04062 | E19: =D19*12*0.97352 -> 7173.3699 | F19: =F18+E19 -> 37805.7 | G19: =IFERROR(IF($F$3="Masculino",B19*(HLOOKUP($C$3,Resgate!$E$1:$BD$87,Resgate!D7,FALSE)),B19*(HLOOKUP($C$3,Resgate!$BF$1:$DE$87,Resgate!D7,FALSE))),"") -> 22554.862 | H19: =G19/F19 -> 0.59659952 | J19: Renda Hospitalar
A20: =IF(A19="","",IF(A19+1>100,"",A19+1)) -> 35 | B20: =IFERROR(IF(A20="","",B19)*(1+$G$3),"") -> 206826.42 | D20: =D19*(1+$G$3) -> 647.81285 | E20: =D20*12*0.97352 -> 7567.9052 | F20: =F19+E20 -> 45373.605 | G20: =IFERROR(IF($F$3="Masculino",B20*(HLOOKUP($C$3,Resgate!$E$1:$BD$87,Resgate!D8,FALSE)),B20*(HLOOKUP($C$3,Resgate!$BF$1:$DE$87,Resgate!D8,FALSE))),"") -> 33317.668 | H20: =G20/F20 -> 0.73429625 | J20: 1000 | K20: =(L20*12)*0.97352 -> 591.02228 | L20: =IF(J20=0,"",IF(J20<300,"Mínimo 300,00",IF(H3="Anual",Simulações!U7,Simulações!U9))) -> 50.59152
A21: =IF(A20="","",IF(A20+1>100,"",A20+1)) -> 36 | B21: =IFERROR(IF(A21="","",B20)*(1+$G$3),"") -> 218201.87 | D21: =D20*(1+$G$3) -> 683.44256 | E21: =D21*12*0.97352 -> 7984.14 | F21: =F20+E21 -> 53357.745 | G21: =IFERROR(IF($F$3="Masculino",B21*(HLOOKUP($C$3,Resgate!$E$1:$BD$87,Resgate!D9,FALSE)),B21*(HLOOKUP($C$3,Resgate!$BF$1:$DE$87,Resgate!D9,FALSE))),"") -> 47072.69 | H21: =G21/F21 -> 0.88220914 | J21: Total | K21: =K20+K18+K16+K14 -> #VALUE! | L21: =SUM(L14,L16,L20,L18) -> #VALUE!
A22: =IF(A21="","",IF(A21+1>100,"",A21+1)) -> 37 | B22: =IFERROR(IF(A22="","",B21)*(1+$G$3),"") -> 230202.98 | D22: =D21*(1+$G$3) -> 721.0319 | E22: =D22*12*0.97352 -> 8423.2677 | F22: =F21+E22 -> 61781.013 | G22: =IFERROR(IF($F$3="Masculino",B22*(HLOOKUP($C$3,Resgate!$E$1:$BD$87,Resgate!D10,FALSE)),B22*(HLOOKUP($C$3,Resgate!$BF$1:$DE$87,Resgate!D10,FALSE))),"") -> 64304.9 | H22: =G22/F22 -> 1.0408521
A23: =IF(A22="","",IF(A22+1>100,"",A22+1)) -> 38 | B23: =IFERROR(IF(A23="","",B22)*(1+$G$3),"") -> 242864.14 | D23: =D22*(1+$G$3) -> 760.68865 | E23: =D23*12*0.97352 -> 8886.5474 | F23: =F22+E23 -> 70667.56 | G23: =IFERROR(IF($F$3="Masculino",B23*(HLOOKUP($C$3,Resgate!$E$1:$BD$87,Resgate!D11,FALSE)),B23*(HLOOKUP($C$3,Resgate!$BF$1:$DE$87,Resgate!D11,FALSE))),"") -> 90066.167 | H23: =G23/$F$23 -> 1.2745051 | J23: =IF(H3="Anual","Total Anual","Total Mensal") -> Total Mensal | K23: =K21+E14 -> #VALUE! | L23: =L21+D14 -> #VALUE!
A24: =IF(A23="","",IF(A23+1>100,"",A23+1)) -> 39 | B24: =IFERROR(IF(A24="","",B23)*(1+$G$3),"") -> 256221.67 | E24: Apólice Quitada | G24: =IFERROR(IF($F$3="Masculino",B24*(HLOOKUP($C$3,Resgate!$E$1:$BD$87,Resgate!D12,FALSE)),B24*(HLOOKUP($C$3,Resgate!$BF$1:$DE$87,Resgate!D12,FALSE))),"") -> 97443.663 | H24: =G24/$F$23 -> 1.3789023 | J24: *Tributação de acordo com a legislação vigente
A25: =IF(A24="","",IF(A24+1>100,"",A24+1)) -> 40 | B25: =IFERROR(IF(A25="","",B24)*(1+$G$3),"") -> 270313.86 | G25: =IFERROR(IF($F$3="Masculino",B25*(HLOOKUP($C$3,Resgate!$E$1:$BD$87,Resgate!D13,FALSE)),B25*(HLOOKUP($C$3,Resgate!$BF$1:$DE$87,Resgate!D13,FALSE))),"") -> 105408.89 | H25: =G25/$F$23 -> 1.4916164
A26: =IF(A25="","",IF(A25+1>100,"",A25+1)) -> 41 | B26: =IFERROR(IF(A26="","",B25)*(1+$G$3),"") -> 285181.12 | G26: =IFERROR(IF($F$3="Masculino",B26*(HLOOKUP($C$3,Resgate!$E$1:$BD$87,Resgate!D14,FALSE)),B26*(HLOOKUP($C$3,Resgate!$BF$1:$DE$87,Resgate!D14,FALSE))),"") -> 114004.01 | H26: =G26/$F$23 -> 1.6132438
A27: =IF(A26="","",IF(A26+1>100,"",A26+1)) -> 42 | B27: =IFERROR(IF(A27="","",B26)*(1+$G$3),"") -> 300866.08 | G27: =IFERROR(IF($F$3="Masculino",B27*(HLOOKUP($C$3,Resgate!$E$1:$BD$87,Resgate!D15,FALSE)),B27*(HLOOKUP($C$3,Resgate!$BF$1:$DE$87,Resgate!D15,FALSE))),"") -> 123276.87 | H27: =G27/$F$23 -> 1.7444619
A28: =IF(A27="","",IF(A27+1>100,"",A27+1)) -> 43 | B28: =IFERROR(IF(A28="","",B27)*(1+$G$3),"") -> 317413.72 | G28: =IFERROR(IF($F$3="Masculino",B28*(HLOOKUP($C$3,Resgate!$E$1:$BD$87,Resgate!D16,FALSE)),B28*(HLOOKUP($C$3,Resgate!$BF$1:$DE$87,Resgate!D16,FALSE))),"") -> 133275.67 | H28: =G28/$F$23 -> 1.8859527
A29: =IF(A28="","",IF(A28+1>100,"",A28+1)) -> 44 | B29: =IFERROR(IF(A29="","",B28)*(1+$G$3),"") -> 334871.47 | G29: =IFERROR(IF($F$3="Masculino",B29*(HLOOKUP($C$3,Resgate!$E$1:$BD$87,Resgate!D17,FALSE)),B29*(HLOOKUP($C$3,Resgate!$BF$1:$DE$87,Resgate!D17,FALSE))),"") -> 144055.01 | H29: =G29/$F$23 -> 2.0384885
A30: =IF(A29="","",IF(A29+1>100,"",A29+1)) -> 45 | B30: =IFERROR(IF(A30="","",B29)*(1+$G$3),"") -> 353289.4 | G30: =IFERROR(IF($F$3="Masculino",B30*(HLOOKUP($C$3,Resgate!$E$1:$BD$87,Resgate!D18,FALSE)),B30*(HLOOKUP($C$3,Resgate!$BF$1:$DE$87,Resgate!D18,FALSE))),"") -> 155673.44 | H30: =G30/$F$23 -> 2.2028982
A31: =IF(A30="","",IF(A30+1>100,"",A30+1)) -> 46 | B31: =IFERROR(IF(A31="","",B30)*(1+$G$3),"") -> 372720.32 | G31: =IFERROR(IF($F$3="Masculino",B31*(HLOOKUP($C$3,Resgate!$E$1:$BD$87,Resgate!D19,FALSE)),B31*(HLOOKUP($C$3,Resgate!$BF$1:$DE$87,Resgate!D19,FALSE))),"") -> 168193.77 | H31: =G31/$F$23 -> 2.3800705
A32: =IF(A31="","",IF(A31+1>100,"",A31+1)) -> 47 | B32: =IFERROR(IF(A32="","",B31)*(1+$G$3),"") -> 393219.94 | G32: =IFERROR(IF($F$3="Masculino",B32*(HLOOKUP($C$3,Resgate!$E$1:$BD$87,Resgate!D20,FALSE)),B32*(HLOOKUP($C$3,Resgate!$BF$1:$DE$87,Resgate!D20,FALSE))),"") -> 181683.34 | H32: =G32/$F$23 -> 2.5709582
A33: =IF(A32="","",IF(A32+1>100,"",A32+1)) -> 48 | B33: =IFERROR(IF(A33="","",B32)*(1+$G$3),"") -> 414847.04 | G33: =IFERROR(IF($F$3="Masculino",B33*(HLOOKUP($C$3,Resgate!$E$1:$BD$87,Resgate!D21,FALSE)),B33*(HLOOKUP($C$3,Resgate!$BF$1:$DE$87,Resgate!D21,FALSE))),"") -> 196218.5 | H33: =G33/$F$23 -> 2.7766418
A34: =IF(A33="","",IF(A33+1>100,"",A33+1)) -> 49 | B34: =IFERROR(IF(A34="","",B33)*(1+$G$3),"") -> 437663.62 | G34: =IFERROR(IF($F$3="Masculino",B34*(HLOOKUP($C$3,Resgate!$E$1:$BD$87,Resgate!D22,FALSE)),B34*(HLOOKUP($C$3,Resgate!$BF$1:$DE$87,Resgate!D22,FALSE))),"") -> 211872.96 | H34: =G34/$F$23 -> 2.9981644
A35: =IF(A34="","",IF(A34+1>100,"",A34+1)) -> 50 | B35: =IFERROR(IF(A35="","",B34)*(1+$G$3),"") -> 461735.12 | G35: =IFERROR(IF($F$3="Masculino",B35*(HLOOKUP($C$3,Resgate!$E$1:$BD$87,Resgate!D23,FALSE)),B35*(HLOOKUP($C$3,Resgate!$BF$1:$DE$87,Resgate!D23,FALSE))),"") -> 228725.11 | H35: =G35/$F$23 -> 3.2366352
A36: =IF(A35="","",IF(A35+1>100,"",A35+1)) -> 51 | B36: =IFERROR(IF(A36="","",B35)*(1+$G$3),"") -> 487130.55 | G36: =IFERROR(IF($F$3="Masculino",B36*(HLOOKUP($C$3,Resgate!$E$1:$BD$87,Resgate!D24,FALSE)),B36*(HLOOKUP($C$3,Resgate!$BF$1:$DE$87,Resgate!D24,FALSE))),"") -> 246863.15 | H36: =G36/$F$23 -> 3.4933023
... A99: =IF(A98="","",IF(A98+1>100,"",A98+1)) | B99: =IFERROR(IF(A99="","",B98)*(1+$G$3),"") | G99: =IFERROR(IF($F$3="Masculino",B99*(HLOOKUP($C$3,Resgate!$E$1:$BD$87,Resgate!D87,FALSE)),B99*(HLOOKUP($C$3,Resgate!$BF$1:$DE$87,Resgate!D87,FALSE))),"") | H99: =G99/$F$23 -> #VALUE!

Sheet Valores IOF
B3: Periodicidade Anual | C3: Prêmio Líquido | D3: IOF | E3: Prêmio Bruto
B4: Vida Inteira | C4: =IF(Simulador!F3="Masculino",SUM(Simulações!F3:F54),SUM(Simulações!H3:H54)) -> 5200.5 | D4: =C4*0.38% -> 19.7619 | E4: =C4+D4 -> 5220.2619
B5: Morte Acidental | C5: =Simulador!J14*Simulações!K3/1000 -> 0 | D5: =C5*0.38% -> 0 | E5: =C5+D5 -> 0
B6: Invalidez Acidental | C6: =Simulador!J16*Simulações!Y3/1000 -> 100 | D6: =C6*0.38% -> 0.38 | E6: =C6+D6 -> 100.38
B7: Doenças Graves Plus | C7: =IF(Simulador!F3="Masculino",SUM(Simulações!AC3:AC54),SUM(Simulações!AE3:AE54)) -> 264 | D7: =C7*0.38% -> 1.0032 | E7: =C7+D7 -> 265.0032
B8: Renda Hospitalar | C8: =IF(Simulador!F3="Masculino",SUM(Simulações!T3:T54),SUM(Simulações!V3:V54)) -> 560 | D8: =C8*0.38% -> 2.128 | E8: =C8+D8 -> 562.128
B9: Total | C9: =SUM(C4:C8) -> 6124.5 | D9: =SUM(D4:D8) -> 23.2731 | E9: =SUM(E4:E8) -> 6147.7731
C10: ]
B12: Periodicidade Mensal | C12: Prêmio Líquido | D12: IOF | E12: Prêmio Bruto
B13: Vida Inteira | C13: 950 | D13: =C13*0.38% -> 3.61 | E13: =C13+D13 -> 953.61
B14: Morte Acidental | C14: =C5*0.09 -> 0 | D14: =C14*0.38% -> 0 | E14: =C14+D14 -> 0
B15: Invalidez Acidental | C15: 10 | D15: =C15*0.38% -> 0.038 | E15: =C15+D15 -> 10.038
B16: Doenças Graves Plus | C16: =C7*0.09 -> 23.76 | D16: =C16*0.38% -> 0.090288 | E16: =C16+D16 -> 23.850288
B17: Renda Hospitalar | C17: =C8*0.09 -> 50.4 | D17: =C17*0.38% -> 0.19152 | E17: =C17+D17 -> 50.59152 | F17: Prêmio Anual Total Fracionado
B18: Total | C18: =SUM(C13:C17) -> 1034.16 | D18: =SUM(D13:D17) -> 3.929808 | E18: =SUM(E13:E17) -> 1038.0898 | F18: =E18*12 -> 12457.078

Sheet Simulações
A1: Idade | B1: WL10 X | C1: WL10 X | D1: Masculino | E1: WL10 Masculino | G1: WL 10 Feminino | J1: Idade | K1: Morte Acidental | O1: Idade | P1: Renda Hospitalar | X1: Idade | Y1: Invalidez Parcial | AF1: Idade | AG1: DDR - Plus | AL1: Idade | AM1: DDR - Básico | AR1: Idade | AS1: WL20 C | AU1: Masculino | AV1: WL20 Masculino | AX1: WL 20 Feminino
B2: Masc | C2: Fem | D2: Feminino | E2: Idade | G2: Idade | K2: Masc | L2: Fem | P2: Masc | Q2: Fem | S2: Masculino | U2: Feminino | Y2: Masc | Z2: Fem | AB2: Masculinio | AD2: Feminino | AG2: Mas | AH2: Fem | AM2: Mas | AN2: Fem | AS2: Masc | AT2: Fem | AU2: Feminino | AV2: Idade | AX2: Idade
A3: 14 | B3: 24.4 | C3: 21.27 | E3: =Simulador!C3 -> 28 | F3: =IF($E$3=A3,$E$5*B3,"") | G3: =Simulador!C3 -> 28 | H3: =IF($G$3=A3,$G$5*C3,"") | J3: 14 | K3: 1.08 | L3: 1.08 | O3: 14 | P3: 0.56 | Q3: 0.56 | R3: =P3-Q3 -> 0 | S3: =Simulador!C3 -> 28 | T3: =IF($S$3=O3,$S$5*P3,"") | U3: =Simulador!C3 -> 28 | V3: =IF($U$3=O3,$U$5*Q3,"") | X3: 14 | Y3: 0.5 | Z3: 0.5 | AB3: =Simulador!C3 -> 28 | AC3: =IF($AB$3=AF3,$AB$5*AG3,"") | AD3: =Simulador!C3 -> 28 | AE3: =IF($AD$3=AF3,$AD$5*AH3,"") | AF3: 14 | AG3: 0.62 | AH3: 0.61 | AL3: 14 | AM3: 0.48 | AN3: 0.49 | AR3: 14 | AS3: 18.05 | AT3: 15.95 | AV3: =Simulador!C3 -> 28 | AW3: =IF($AV$3=AR3,$AV$5*AS3,"") | AX3: =Simulador!C3 -> 28 | AY3: =IF($AX$3=AR3,$AX$5*AT3,"")
A4: 15 | B4: 25.03 | C4: 21.83 | E4: Capital Segurado | F4: =IF($E$3=A4,$E$5*B4,"") | G4: Capital Segurado | H4: =IF($G$3=A4,$G$5*C4,"") | O4: =O3+1 -> 15 | P4: 0.56 | Q4: 0.56 | R4: =P4-Q4 -> 0 | S4: Capital Segurado | T4: =IF($S$3=O4,$S$5*P4,"") | U4: Capital Segurado | V4: =IF($U$3=O4,$U$5*Q4,"") | AB4: Capital Segurado | AC4: =IF($AB$3=AF4,$AB$5*AG4,"") | AD4: Capital Segurado | AE4: =IF($AD$3=AF4,$AD$5*AH4,"") | AF4: =AF3+1 -> 15 | AG4: 0.62 | AH4: 0.61 | AL4: =AL3+1 -> 15 | AM4: 0.48 | AN4: 0.49 | AR4: 15 | AS4: 18.51 | AT4: 16.37 | AV4: Capital Segurado | AW4: =IF($AV$3=AR4,$AV$5*AS4,"") | AX4: Capital Segurado | AY4: =IF($AX$3=AR4,$AX$5*AT4,"")
A5: 16 | B5: 25.66 | C5: 22.4 | E5: =Simulador!E3/1000 -> 150 | F5: =IF($E$3=A5,$E$5*B5,"") | G5: =Simulador!E3/1000 -> 150 | H5: =IF($G$3=A5,$G$5*C5,"") | K5: Idade | O5: =O4+1 -> 16 | P5: 0.56 | Q5: 0.56 | R5: =P5-Q5 -> 0 | S5: =Simulador!J20 -> 1000 | T5: =IF($S$3=O5,$S$5*P5,"") | U5: =Simulador!J20 -> 1000 | V5: =IF($U$3=O5,$U$5*Q5,"") | Y5: Idade | AB5: =Simulador!J18/1000 -> 200 | AC5: =IF($AB$3=AF5,$AB$5*AG5,"") | AD5: =Simulador!J18/1000 -> 200 | AE5: =IF($AD$3=AF5,$AD$5*AH5,"") | AF5: =AF4+1 -> 16 | AG5: 0.62 | AH5: 0.61 | AL5: =AL4+1 -> 16 | AM5: 0.48 | AN5: 0.49 | AR5: 16 | AS5: 18.97 | AT5: 16.8 | AV5: =Simulador!E3/1000 -> 150 | AW5: =IF($AV$3=AR5,$AV$5*AS5,"") | AX5: =Simulador!E3/1000 -> 150 | AY5: =IF($AX$3=AR5,$AX$5*AT5,"")
A6: 17 | B6: 26.28 | C6: 22.99 | E6: Prêmio Anual | F6: =IF($E$3=A6,$E$5*B6,"") | G6: Prêmio Anual | H6: =IF($G$3=A6,$G$5*C6,"") | K6: =G3 -> 28 | O6: =O5+1 -> 17 | P6: 0.56 | Q6: 0.56 | R6: =P6-Q6 -> 0 | S6: Prêmio Anual | T6: =IF($S$3=O6,$S$5*P6,"") | U6: Prêmio Anual | V6: =IF($U$3=O6,$U$5*Q6,"") | Y6: =U3 -> 28 | AB6: Prêmio Anual | AC6: =IF($AB$3=AF6,$AB$5*AG6,"") | AD6: Prêmio Anual | AE6: =IF($AD$3=AF6,$AD$5*AH6,"") | AF6: =AF5+1 -> 17 | AG6: 0.63 | AH6: 0.62 | AL6: =AL5+1 -> 17 | AM6: 0.48 | AN6: 0.5 | AR6: 17 | AS6: 19.44 | AT6: 17.24 | AV6: Prêmio Anual | AW6: =IF($AV$3=AR6,$AV$5*AS6,"") | AX6: Prêmio Anual | AY6: =IF($AX$3=AR6,$AX$5*AT6,"")
A7: 18 | B7: 26.91 | C7: 23.59 | E7: =(IF(F3:F54<=0,"",SUM(F3:F54))*0.38%+(IF(F3:F54<=0,"",SUM(F3:F54)))) -> 5220.2619 | F7: =IF($E$3=A7,$E$5*B7,"") | G7: =IF(H3:H54<=0,"",SUM(H3:H54))*0.38%+(IF(H3:H54<=0,"",SUM(H3:H54))) -> 4700.7954 | H7: =IF($G$3=A7,$G$5*C7,"") | K7: Capital Segurado | O7: =O6+1 -> 18 | P7: 0.56 | Q7: 0.56 | R7: =P7-Q7 -> 0 | S7: =IF(OR(S5<300,S5>1500,),"Máximo 1.500,00",(IF(T3:T54<=0,"",SUM(T3:T54)))*0.38%+(IF(T3:T54<=0,"",SUM(T3:T54)))) -> 562.128 | T7: =IF($S$3=O7,$S$5*P7,"") | U7: =IF(OR(U5<300,U5>1500,),"Máximo 1.500,00",(IF(V3:V54<=0,"",SUM(V3:V54)))*0.38%+(IF(V3:V54<=0,"",SUM(V3:V54)))) -> 562.128 | V7: =IF($U$3=O7,$U$5*Q7,"") | Y7: Capital Segurado | AB7: =IF(E5<160,"Capital Mínimo R$ 160k",(IF(AC3:AC54<=0,"",SUM(AC3:AC54)))*0.38%+(IF(AC3:AC54<=0,"",SUM(AC3:AC54)))) -> Capital Mínimo R$ 160k | AC7: =IF($AB$3=AF7,$AB$5*AG7,"") | AD7: =IF(G5<160,"Capital Mínimo R$ 160k",(IF(AE3:AE54<=0,"",SUM(AE3:AE54)))*0.38%+(IF(AE3:AE54<=0,"",SUM(AE3:AE54)))) -> Capital Mínimo R$ 160k | AE7: =IF($AD$3=AF7,$AD$5*AH7,"") | AF7: =AF6+1 -> 18 | AG7: 0.66 | AH7: 0.64 | AL7: =AL6+1 -> 18 | AM7: 0.5 | AN7: 0.52 | AR7: 18 | AS7: 19.9 | AT7: 17.7 | AV7: =IF(AV5<160,"Capital Mínimo R$ 160k",(IF(AW3:AW54<=0,"",SUM(AW3:AW54)))*0.38%+(IF(AW3:AW54<=0,"",SUM(AW3:AW54)))) -> Capital Mínimo R$ 160k | AW7: =IF($AV$3=AR7,$AV$5*AS7,"") | AX7: =IF(AX5<160,"Capital Mínimo R$ 160k",(IF(AY3:AY54<=0,"",SUM(AY3:AY54)))*0.38%+(IF(AY3:AY54<=0,"",SUM(AY3:AY54)))) -> Capital Mínimo R$ 160k | AY7: =IF($AX$3=AR7,$AX$5*AT7,"")
A8: 19 | B8: 27.55 | C8: 24.2 | E8: Prêmio Mensal | F8: =IF($E$3=A8,$E$5*B8,"") | G8: Prêmio Mensal | H8: =IF($G$3=A8,$G$5*C8,"") | K8: =Simulador!J14 -> 0 | O8: =O7+1 -> 19 | P8: 0.56 | Q8: 0.56 | R8: =P8-Q8 -> 0 | S8: Prêmio Mensal | T8: =IF($S$3=O8,$S$5*P8,"") | U8: Prêmio Mensal | V8: =IF($U$3=O8,$U$5*Q8,"") | Y8: =Simulador!J16 -> 200000 | AB8: Prêmio Mensal | AC8: =IF($AB$3=AF8,$AB$5*AG8,"") | AD8: Prêmio Mensal | AE8: =IF($AD$3=AF8,$AD$5*AH8,"") | AF8: =AF7+1 -> 19 | AG8: 0.69 | AH8: 0.67 | AL8: =AL7+1 -> 19 | AM8: 0.53 | AN8: 0.54 | AR8: 19 | AS8: 20.38 | AT8: 18.16 | AV8: Prêmio Mensal | AW8: =IF($AV$3=AR8,$AV$5*AS8,"") | AX8: Prêmio Mensal | AY8: =IF($AX$3=AR8,$AX$5*AT8,"")
A9: 20 | B9: 28.21 | C9: 24.83 | E9: =E7*0.09 -> 469.82357 | F9: =IF($E$3=A9,$E$5*B9,"") | G9: =G7*0.09 -> 423.07159 | H9: =IF($G$3=A9,$G$5*C9,"") | K9: Prêmio Anual | O9: =O8+1 -> 20 | P9: 0.56 | Q9: 0.56 | R9: =P9-Q9 -> 0 | S9: =S7*0.09 -> 50.59152 | T9: =IF($S$3=O9,$S$5*P9,"") | U9: =U7*0.09 -> 50.59152 | V9: =IF($U$3=O9,$U$5*Q9,"") | Y9: Prêmio Anual | AB9: =AB7*0.09 -> #VALUE! | AC9: =IF($AB$3=AF9,$AB$5*AG9,"") | AD9: =AD7*0.09 -> #VALUE! | AE9: =IF($AD$3=AF9,$AD$5*AH9,"") | AF9: =AF8+1 -> 20 | AG9: 0.73 | AH9: 0.71 | AL9: =AL8+1 -> 20 | AM9: 0.56 | AN9: 0.57 | AR9: 20 | AS9: 20.86 | AT9: 18.64 | AV9: =AV7*0.09 -> #VALUE! | AW9: =IF($AV$3=AR9,$AV$5*AS9,"") | AX9: =AX7*0.09 -> #VALUE! | AY9: =IF($AX$3=AR9,$AX$5*AT9,"")
A10: 21 | B10: 28.88 | C10: 25.48 | F10: =IF($E$3=A10,$E$5*B10,"") | H10: =IF($G$3=A10,$G$5*C10,"") | K10: =(K8/1000*K3)*0.38%+((K8/1000*K3)) -> 0 | O10: =O9+1 -> 21 | P10: 0.56 | Q10: 0.56 | R10: =P10-Q10 -> 0 | T10: =IF($S$3=O10,$S$5*P10,"") | V10: =IF($U$3=O10,$U$5*Q10,"") | Y10: =(Y8/1000*Y3)*0.38%+((Y8/1000*Y3)) -> 100.38 | AC10: =IF($AB$3=AF10,$AB$5*AG10,"") | AE10: =IF($AD$3=AF10,$AD$5*AH10,"") | AF10: =AF9+1 -> 21 | AG10: 0.8 | AH10: 0.77 | AL10: =AL9+1 -> 21 | AM10: 0.6 | AN10: 0.61 | AR10: 21 | AS10: 21.36 | AT10: 19.13 | AW10: =IF($AV$3=AR10,$AV$5*AS10,"") | AY10: =IF($AX$3=AR10,$AX$5*AT10,"")
A11: 22 | B11: 29.57 | C11: 26.15 | F11: =IF($E$3=A11,$E$5*B11,"") | H11: =IF($G$3=A11,$G$5*C11,"") | I11: =IF(G4="Anual",IF(H4=0,IF(E4="Masculino",Simulações!AB7,Simulações!AD7),H4),IF(H4=0,IF(E4="Masculino",Simulações!E9,Simulações!G9),H4)) | K11: Prêmio Mensal | O11: =O10+1 -> 22 | P11: 0.56 | Q11: 0.56 | R11: =P11-Q11 -> 0 | T11: =IF($S$3=O11,$S$5*P11,"") | V11: =IF($U$3=O11,$U$5*Q11,"") | Y11: Prêmio Mensal | AC11: =IF($AB$3=AF11,$AB$5*AG11,"") | AE11: =IF($AD$3=AF11,$AD$5*AH11,"") | AF11: =AF10+1 -> 22 | AG11: 0.86 | AH11: 0.83 | AL11: =AL10+1 -> 22 | AM11: 0.65 | AN11: 0.66 | AR11: 22 | AS11: 21.88 | AT11: 19.63 | AW11: =IF($AV$3=AR11,$AV$5*AS11,"") | AY11: =IF($AX$3=AR11,$AX$5*AT11,"")
A12: 23 | B12: 30.29 | C12: 26.83 | F12: =IF($E$3=A12,$E$5*B12,"") | H12: =IF($G$3=A12,$G$5*C12,"") | K12: =K10*0.09 -> 0 | O12: =O11+1 -> 23 | P12: 0.56 | Q12: 0.56 | R12: =P12-Q12 -> 0 | T12: =IF($S$3=O12,$S$5*P12,"") | V12: =IF($U$3=O12,$U$5*Q12,"") | Y12: =Y10*0.09 -> 9.0342 | AC12: =IF($AB$3=AF12,$AB$5*AG12,"") | AE12: =IF($AD$3=AF12,$AD$5*AH12,"") | AF12: =AF11+1 -> 23 | AG12: 0.93 | AH12: 0.89 | AL12: =AL11+1 -> 23 | AM12: 0.7 | AN12: 0.7 | AR12: 23 | AS12: 22.27 | AT12: 20.15 | AW12: =IF($AV$3=AR12,$AV$5*AS12,"") | AY12: =IF($AX$3=AR12,$AX$5*AT12,"")
A13: 24 | B13: 31.03 | C13: 27.54 | F13: =IF($E$3=A13,$E$5*B13,"") | H13: =IF($G$3=A13,$G$5*C13,"") | O13: =O12+1 -> 24 | P13: 0.56 | Q13: 0.56 | R13: =P13-Q13 -> 0 | T13: =IF($S$3=O13,$S$5*P13,"") | V13: =IF($U$3=O13,$U$5*Q13,"") | AC13: =IF($AB$3=AF13,$AB$5*AG13,"") | AE13: =IF($AD$3=AF13,$AD$5*AH13,"") | AF13: =AF12+1 -> 24 | AG13: 1 | AH13: 0.97 | AL13: =AL12+1 -> 24 | AM13: 0.76 | AN13: 0.76 | AR13: 24 | AS13: 22.67 | AT13: 20.69 | AW13: =IF($AV$3=AR13,$AV$5*AS13,"") | AY13: =IF($AX$3=AR13,$AX$5*AT13,"")
A14: 25 | B14: 32.14 | C14: 28.87 | F14: =IF($E$3=A14,$E$5*B14,"") | H14: =IF($G$3=A14,$G$5*C14,"") | O14: =O13+1 -> 25 | P14: 0.56 | Q14: 0.56 | R14: =P14-Q14 -> 0 | T14: =IF($S$3=O14,$S$5*P14,"") | V14: =IF($U$3=O14,$U$5*Q14,"") | AC14: =IF($AB$3=AF14,$AB$5*AG14,"") | AE14: =IF($AD$3=AF14,$AD$5*AH14,"") | AF14: =AF13+1 -> 25 | AG14: 1.08 | AH14: 1.05 | AL14: =AL13+1 -> 25 | AM14: 0.81 | AN14: 0.83 | AR14: 25 | AS14: 22.95 | AT14: 20.96 | AW14: =IF($AV$3=AR14,$AV$5*AS14,"") | AY14: =IF($AX$3=AR14,$AX$5*AT14,"")
A15: 26 | B15: 32.95 | C15: 29.63 | F15: =IF($E$3=A15,$E$5*B15,"") | H15: =IF($G$3=A15,$G$5*C15,"") | O15: =O14+1 -> 26 | P15: 0.56 | Q15: 0.56 | R15: =P15-Q15 -> 0 | T15: =IF($S$3=O15,$S$5*P15,"") | V15: =IF($U$3=O15,$U$5*Q15,"") | AC15: =IF($AB$3=AF15,$AB$5*AG15,"") | AE15: =IF($AD$3=AF15,$AD$5*AH15,"") | AF15: =AF14+1 -> 26 | AG15: 1.16 | AH15: 1.16 | AL15: =AL14+1 -> 26 | AM15: 0.88 | AN15: 0.92 | AR15: 26 | AS15: 23.24 | AT15: 21.23 | AW15: =IF($AV$3=AR15,$AV$5*AS15,"") | AY15: =IF($AX$3=AR15,$AX$5*AT15,"")
A16: 27 | B16: 33.79 | C16: 30.42 | F16: =IF($E$3=A16,$E$5*B16,"") | H16: =IF($G$3=A16,$G$5*C16,"") | O16: =O15+1 -> 27 | P16: 0.56 | Q16: 0.56 | R16: =P16-Q16 -> 0 | T16: =IF($S$3=O16,$S$5*P16,"") | V16: =IF($U$3=O16,$U$5*Q16,"") | AC16: =IF($AB$3=AF16,$AB$5*AG16,"") | AE16: =IF($AD$3=AF16,$AD$5*AH16,"") | AF16: =AF15+1 -> 27 | AG16: 1.24 | AH16: 1.27 | AL16: =AL15+1 -> 27 | AM16: 0.95 | AN16: 1.03 | AR16: 27 | AS16: 23.69 | AT16: 21.52 | AW16: =IF($AV$3=AR16,$AV$5*AS16,"") | AY16: =IF($AX$3=AR16,$AX$5*AT16,"")
A17: 28 | B17: 34.67 | C17: 31.22 | F17: =IF($E$3=A17,$E$5*B17,"") -> 5200.5 | H17: =IF($G$3=A17,$G$5*C17,"") -> 4683 | O17: =O16+1 -> 28 | P17: 0.56 | Q17: 0.56 | R17: =P17-Q17 -> 0 | T17: =IF($S$3=O17,$S$5*P17,"") -> 560 | V17: =IF($U$3=O17,$U$5*Q17,"") -> 560 | AC17: =IF($AB$3=AF17,$AB$5*AG17,"") -> 264 | AE17: =IF($AD$3=AF17,$AD$5*AH17,"") -> 282 | AF17: =AF16+1 -> 28 | AG17: 1.32 | AH17: 1.41 | AL17: =AL16+1 -> 28 | AM17: 1.03 | AN17: 1.16 | AR17: 28 | AS17: 24.17 | AT17: 22.1 | AW17: =IF($AV$3=AR17,$AV$5*AS17,"") -> 3625.5 | AY17: =IF($AX$3=AR17,$AX$5*AT17,"") -> 3315
A18: 29 | B18: 35.57 | C18: 32.05 | F18: =IF($E$3=A18,$E$5*B18,"") | H18: =IF($G$3=A18,$G$5*C18,"") | O18: =O17+1 -> 29 | P18: 0.56 | Q18: 0.56 | R18: =P18-Q18 -> 0 | T18: =IF($S$3=O18,$S$5*P18,"") | V18: =IF($U$3=O18,$U$5*Q18,"") | AC18: =IF($AB$3=AF18,$AB$5*AG18,"") | AE18: =IF($AD$3=AF18,$AD$5*AH18,"") | AF18: =AF17+1 -> 29 | AG18: 1.42 | AH18: 1.57 | AL18: =AL17+1 -> 29 | AM18: 1.11 | AN18: 1.31 | AR18: 29 | AS18: 24.82 | AT18: 22.55 | AW18: =IF($AV$3=AR18,$AV$5*AS18,"") | AY18: =IF($AX$3=AR18,$AX$5*AT18,"")
A19: 30 | B19: 36.5 | C19: 32.9 | F19: =IF($E$3=A19,$E$5*B19,"") | H19: =IF($G$3=A19,$G$5*C19,"") | O19: =O18+1 -> 30 | P19: 0.56 | Q19: 0.56 | R19: =P19-Q19 -> 0 | T19: =IF($S$3=O19,$S$5*P19,"") | V19: =IF($U$3=O19,$U$5*Q19,"") | AC19: =IF($AB$3=AF19,$AB$5*AG19,"") | AE19: =IF($AD$3=AF19,$AD$5*AH19,"") | AF19: =AF18+1 -> 30 | AG19: 1.53 | AH19: 1.74 | AL19: =AL18+1 -> 30 | AM19: 1.21 | AN19: 1.47 | AR19: 30 | AS19: 25.5 | AT19: 23.17 | AW19: =IF($AV$3=AR19,$AV$5*AS19,"") | AY19: =IF($AX$3=AR19,$AX$5*AT19,"")
A20: 31 | B20: 37.47 | C20: 33.78 | F20: =IF($E$3=A20,$E$5*B20,"") | H20: =IF($G$3=A20,$G$5*C20,"") | O20: =O19+1 -> 31 | P20: 0.59 | Q20: 0.59 | R20: =P20-Q20 -> 0 | T20: =IF($S$3=O20,$S$5*P20,"") | V20: =IF($U$3=O20,$U$5*Q20,"") | AC20: =IF($AB$3=AF20,$AB$5*AG20,"") | AE20: =IF($AD$3=AF20,$AD$5*AH20,"") | AF20: =AF19+1 -> 31 | AG20: 1.65 | AH20: 1.93 | AL20: =AL19+1 -> 31 | AM20: 1.33 | AN20: 1.66 | AR20: 31 | AS20: 26.2 | AT20: 23.5 | AW20: =IF($AV$3=AR20,$AV$5*AS20,"") | AY20: =IF($AX$3=AR20,$AX$5*AT20,"")
A21: 32 | B21: 38.46 | C21: 34.68 | F21: =IF($E$3=A21,$E$5*B21,"") | H21: =IF($G$3=A21,$G$5*C21,"") | O21: =O20+1 -> 32 | P21: 0.62 | Q21: 0.63 | R21: =P21-Q21 -> -0.01 | T21: =IF($S$3=O21,$S$5*P21,"") | V21: =IF($U$3=O21,$U$5*Q21,"") | AC21: =IF($AB$3=AF21,$AB$5*AG21,"") | AE21: =IF($AD$3=AF21,$AD$5*AH21,"") | AF21: =AF20+1 -> 32 | AG21: 1.78 | AH21: 2.13 | AL21: =AL20+1 -> 32 | AM21: 1.46 | AN21: 1.85 | AR21: 32 | AS21: 26.92 | AT21: 23.99 | AW21: =IF($AV$3=AR21,$AV$5*AS21,"") | AY21: =IF($AX$3=AR21,$AX$5*AT21,"")
A22: 33 | B22: 39.49 | C22: 35.61 | F22: =IF($E$3=A22,$E$5*B22,"") | H22: =IF($G$3=A22,$G$5*C22,"") | O22: =O21+1 -> 33 | P22: 0.66 | Q22: 0.66 | R22: =P22-Q22 -> 0 | T22: =IF($S$3=O22,$S$5*P22,"") | V22: =IF($U$3=O22,$U$5*Q22,"") | AC22: =IF($AB$3=AF22,$AB$5*AG22,"") | AE22: =IF($AD$3=AF22,$AD$5*AH22,"") | AF22: =AF21+1 -> 33 | AG22: 1.95 | AH22: 2.35 | AL22: =AL21+1 -> 33 | AM22: 1.62 | AN22: 2.07 | AR22: 33 | AS22: 27.67 | AT22: 24.5 | AW22: =IF($AV$3=AR22,$AV$5*AS22,"") | AY22: =IF($AX$3=AR22,$AX$5*AT22,"")
A23: 34 | B23: 40.54 | C23: 35.98 | F23: =IF($E$3=A23,$E$5*B23,"") | H23: =IF($G$3=A23,$G$5*C23,"") | O23: =O22+1 -> 34 | P23: 0.69 | Q23: 0.69 | R23: =P23-Q23 -> 0 | T23: =IF($S$3=O23,$S$5*P23,"") | V23: =IF($U$3=O23,$U$5*Q23,"") | AC23: =IF($AB$3=AF23,$AB$5*AG23,"") | AE23: =IF($AD$3=AF23,$AD$5*AH23,"") | AF23: =AF22+1 -> 34 | AG23: 2.13 | AH23: 2.6 | AL23: =AL22+1 -> 34 | AM23: 1.81 | AN23: 2.32 | AR23: 34 | AS23: 28.45 | AT23: 25.02 | AW23: =IF($AV$3=AR23,$AV$5*AS23,"") | AY23: =IF($AX$3=AR23,$AX$5*AT23,"")
A24: 35 | B24: 40.98 | C24: 36.37 | F24: =IF($E$3=A24,$E$5*B24,"") | H24: =IF($G$3=A24,$G$5*C24,"") | O24: =O23+1 -> 35 | P24: 0.72 | Q24: 0.72 | R24: =P24-Q24 -> 0 | T24: =IF($S$3=O24,$S$5*P24,"") | V24: =IF($U$3=O24,$U$5*Q24,"") | AC24: =IF($AB$3=AF24,$AB$5*AG24,"") | AE24: =IF($AD$3=AF24,$AD$5*AH24,"") | AF24: =AF23+1 -> 35 | AG24: 2.35 | AH24: 2.86 | AL24: =AL23+1 -> 35 | AM24: 2.02 | AN24: 2.58 | AR24: 35 | AS24: 28.89 | AT24: 25.39 | AW24: =IF($AV$3=AR24,$AV$5*AS24,"") | AY24: =IF($AX$3=AR24,$AX$5*AT24,"")
... A54: 65 | B54: 89.22 | C54: 76.56 | F54: =IF($E$3=A54,$E$5*B54,"") | H54: =IF($G$3=A54,$G$5*C54,"") | O54: =O53+1 -> 65 | P54: 2.82 | Q54: 2.83 | R54: =P54-Q54 -> -0.01 | T54: =IF($S$3=O54,$S$5*P54,"") | V54: =IF($U$3=O54,$U$5*Q54,"") | AC54: =IF($AB$3=AF54,$AB$5*AG54,"") | AE54: =IF($AD$3=AF54,$AD$5*AH54,"") | AF54: =AF53+1 -> 65 | AG54: 42.25 | AH54: 30.45 | AL54: =AL53+1 -> 65 | AM54: 39.47 | AN54: 28.95 | AR54: 65 | AS54: 74.27 | AT54: 62.09 | AW54: =IF($AV$3=AR54,$AV$5*AS54,"") | AY54: =IF($AX$3=AR54,$AX$5*AT54,"")
AR55: 66 | AW55: =IF($AV$3=AR55,$AV$5*AS55,"") | AY55: =IF($AX$3=AR55,$AX$5*AT55,"")
AR56: 67 | AW56: =IF($AV$3=AR56,$AV$5*AS56,"") | AY56: =IF($AX$3=AR56,$AX$5*AT56,"")
AR57: 68 | AW57: =IF($AV$3=AR57,$AV$5*AS57,"") | AY57: =IF($AX$3=AR57,$AX$5*AT57,"")
AR58: 69 | AW58: =IF($AV$3=AR58,$AV$5*AS58,"") | AY58: =IF($AX$3=AR58,$AX$5*AT58,"")
AR59: 70 | AW59: =IF($AV$3=AR59,$AV$5*AS59,"") | AY59: =IF($AX$3=AR59,$AX$5*AT59,"")
AR60: 71 | AW60: =IF($AV$3=AR60,$AV$5*AS60,"") | AY60: =IF($AX$3=AR60,$AX$5*AT60,"")
AR61: 72 | AW61: =IF($AV$3=AR61,$AV$5*AS61,"") | AY61: =IF($AX$3=AR61,$AX$5*AT61,"")
AR62: 73 | AW62: =IF($AV$3=AR62,$AV$5*AS62,"") | AY62: =IF($AX$3=AR62,$AX$5*AT62,"")
AR63: 74 | AW63: =IF($AV$3=AR63,$AV$5*AS63,"") | AY63: =IF($AX$3=AR63,$AX$5*AT63,"")
AR64: 75 | AW64: =IF($AV$3=AR64,$AV$5*AS64,"") | AY64: =IF($AX$3=AR64,$AX$5*AT64,"")

Sheet Resgate
D1: 1 | E1: 14 | F1: 15 | G1: 16 | H1: 17 | I1: 18 | J1: 19 | K1: 20 | L1: 21 | M1: 22 | N1: 23 | O1: 24 | P1: 25 | Q1: 26 | R1: 27 | S1: 28 | T1: 29 | U1: 30 | V1: 31 | W1: 32 | X1: 33 | Y1: 34 | Z1: 35 | AA1: 36 | AB1: 37 | AC1: 38 | AD1: 39 | AE1: 40 | AF1: 41 | AG1: 42 | AH1: 43 | AI1: 44 | AJ1: 45 | AK1: 46 | AL1: 47 | AM1: 48 | AN1: 49 | AO1: 50 | AP1: 51 | AQ1: 52 | AR1: 53 | AS1: 54 | AT1: 55 | AU1: 56 | AV1: 57 | AW1: 58 | AX1: 59 | AY1: 60 | AZ1: 61 | BA1: 62 | BB1: 63 | BC1: 64 | BD1: 65 | BF1: 14 | BG1: 15 | BH1: 16 | BI1: 17 | BJ1: 18 | BK1: 19 | BL1: 20 | BM1: 21 | BN1: 22 | BO1: 23 | BP1: 24 | BQ1: 25 | BR1: 26 | BS1: 27 | BT1: 28 | BU1: 29 | BV1: 30 | BW1: 31 | BX1: 32 | BY1: 33 | BZ1: 34 | CA1: 35 | CB1: 36 | CC1: 37 | CD1: 38 | CE1: 39 | CF1: 40 | CG1: 41 | CH1: 42 | CI1: 43 | CJ1: 44 | CK1: 45 | CL1: 46 | CM1: 47 | CN1: 48 | CO1: 49 | CP1: 50 | CQ1: 51 | CR1: 52 | CS1: 53 | CT1: 54 | CU1: 55 | CV1: 56 | CW1: 57 | CX1: 58 | CY1: 59 | CZ1: 60 | DA1: 61 | DB1: 62 | DC1: 63 | DD1: 64 | DE1: 65
A2: =Simulador!D14 -> 469.82357 | D2: 2 | E2: 0 | F2: 0 | G2: 0 | H2: 0 | I2: 0 | J2: 0 | K2: 0 | L2: 0 | M2: 0 | N2: 0 | O2: 0 | P2: 0 | Q2: 0 | R2: 0 | S2: 0 | T2: 0 | U2: 0 | V2: 0 | W2: 0 | X2: 0 | Y2: 0 | Z2: 0 | AA2: 0 | AB2: 0 | AC2: 0 | AD2: 0 | AE2: 0 | AF2: 0 | AG2: 0 | AH2: 0 | AI2: 0 | AJ2: 0 | AK2: 0 | AL2: 0 | AM2: 0 | AN2: 0 | AO2: 0 | AP2: 0 | AQ2: 0 | AR2: 0 | AS2: 0 | AT2: 0 | AU2: 0 | AV2: 0 | AW2: 0 | AX2: 0 | AY2: 0 | AZ2: 0 | BA2: 0 | BB2: 0 | BC2: 0 | BD2: 0 | BF2: 0 | BG2: 0 | BH2: 0 | BI2: 0 | BJ2: 0 | BK2: 0 | BL2: 0 | BM2: 0 | BN2: 0 | BO2: 0 | BP2: 0 | BQ2: 0 | BR2: 0 | BS2: 0 | BT2: 0 | BU2: 0 | BV2: 0 | BW2: 0 | BX2: 0 | BY2: 0 | BZ2: 0 | CA2: 0 | CB2: 0 | CC2: 0 | CD2: 0 | CE2: 0 | CF2: 0 | CG2: 0 | CH2: 0 | CI2: 0 | CJ2: 0 | CK2: 0 | CL2: 0 | CM2: 0 | CN2: 0 | CO2: 0 | CP2: 0 | CQ2: 0 | CR2: 0 | CS2: 0 | CT2: 0 | CU2: 0 | CV2: 0 | CW2: 0 | CX2: 0 | CY2: 0 | CZ2: 0 | DA2: 0 | DB2: 0 | DC2: 0 | DD2: 0 | DE2: 0
A3: =A2*(1+Simulador!$G$3) -> 495.66387 | D3: 3 | E3: 0 | F3: 0 | G3: 0 | H3: 0 | I3: 0 | J3: 0 | K3: 0 | L3: 0 | M3: 0 | N3: 0 | O3: 0 | P3: 0 | Q3: 0 | R3: 0 | S3: 0 | T3: 0 | U3: 0 | V3: 0 | W3: 0 | X3: 0 | Y3: 0 | Z3: 0 | AA3: 0 | AB3: 0 | AC3: 0 | AD3: 0 | AE3: 0 | AF3: 0 | AG3: 0 | AH3: 0 | AI3: 0 | AJ3: 0 | AK3: 0 | AL3: 0 | AM3: 0 | AN3: 0 | AO3: 0 | AP3: 0 | AQ3: 0 | AR3: 0 | AS3: 0 | AT3: 0 | AU3: 0 | AV3: 0 | AW3: 0 | AX3: 0 | AY3: 0 | AZ3: 0 | BA3: 0 | BB3: 0 | BC3: 0 | BD3: 0 | BF3: 0 | BG3: 0 | BH3: 0 | BI3: 0 | BJ3: 0 | BK3: 0 | BL3: 0 | BM3: 0 | BN3: 0 | BO3: 0 | BP3: 0 | BQ3: 0 | BR3: 0 | BS3: 0 | BT3: 0 | BU3: 0 | BV3: 0 | BW3: 0 | BX3: 0 | BY3: 0 | BZ3: 0 | CA3: 0 | CB3: 0 | CC3: 0 | CD3: 0 | CE3: 0 | CF3: 0 | CG3: 0 | CH3: 0 | CI3: 0 | CJ3: 0 | CK3: 0 | CL3: 0 | CM3: 0 | CN3: 0 | CO3: 0 | CP3: 0 | CQ3: 0 | CR3: 0 | CS3: 0 | CT3: 0 | CU3: 0 | CV3: 0 | CW3: 0 | CX3: 0 | CY3: 0 | CZ3: 0 | DA3: 0 | DB3: 0 | DC3: 0 | DD3: 0 | DE3: 0
A4: =A3*(1+Simulador!$G$3) -> 522.92538 | D4: 4 | E4: 0.01056 | F4: 0.01078 | G4: 0.01101 | H4: 0.01125 | I4: 0.01017 | J4: 0.0118 | K4: 0.0121 | L4: 0.01241 | M4: 0.01275 | N4: 0.0131 | O4: 0.01346 | P4: 0.01383 | Q4: 0.0142 | R4: 0.01459 | S4: 0.01498 | T4: 0.01538 | U4: 0.01578 | V4: 0.01619 | W4: 0.01661 | X4: 0.01703 | Y4: 0.01746 | Z4: 0.01789 | AA4: 0.01833 | AB4: 0.01877 | AC4: 0.01922 | AD4: 0.01966 | AE4: 0.02011 | AF4: 0.02056 | AG4: 0.02102 | AH4: 0.02148 | AI4: 0.02195 | AJ4: 0.02242 | AK4: 0.0229 | AL4: 0.02338 | AM4: 0.02387 | AN4: 0.02435 | AO4: 0.02482 | AP4: 0.02528 | AQ4: 0.02573 | AR4: 0.02617 | AS4: 0.0266 | AT4: 0.02703 | AU4: 0.02746 | AV4: 0.02789 | AW4: 0.02831 | AX4: 0.02871 | AY4: 0.02909 | AZ4: 0.02944 | BA4: 0.02975 | BB4: 0.03002 | BC4: 0.03028 | BD4: 0.03053 | BF4: 0.00926 | BG4: 0.0095 | BH4: 0.00974 | BI4: 0.00999 | BJ4: 0.01025 | BK4: 0.01051 | BL4: 0.01079 | BM4: 0.01108 | BN4: 0.01137 | BO4: 0.01167 | BP4: 0.01198 | BQ4: 0.01229 | BR4: 0.01262 | BS4: 0.01295 | BT4: 0.01329 | BU4: 0.01364 | BV4: 0.01399 | BW4: 0.01436 | BX4: 0.01473 | BY4: 0.01511 | BZ4: 0.0155 | CA4: 0.01589 | CB4: 0.01628 | CC4: 0.01667 | CD4: 0.01706 | CE4: 0.01745 | CF4: 0.01785 | CG4: 0.01826 | CH4: 0.01868 | CI4: 0.0191 | CJ4: 0.01953 | CK4: 0.01997 | CL4: 0.02042 | CM4: 0.02087 | CN4: 0.02133 | CO4: 0.02179 | CP4: 0.02225 | CQ4: 0.02271 | CR4: 0.02316 | CS4: 0.02363 | CT4: 0.0241 | CU4: 0.0246 | CV4: 0.02512 | CW4: 0.02566 | CX4: 0.0262 | CY4: 0.02675 | CZ4: 0.02727 | DA4: 0.02776 | DB4: 0.02821 | DC4: 0.02863 | DD4: 0.02905 | DE4: 0.02949
A5: =A4*(1+Simulador!$G$3) -> 551.68628 | D5: 5 | E5: 0.02663 | F5: 0.0272 | G5: 0.02779 | H5: 0.02844 | I5: 0.02912 | J5: 0.02985 | K5: 0.03061 | L5: 0.03142 | M5: 0.03227 | N5: 0.03314 | O5: 0.03405 | P5: 0.03497 | Q5: 0.03592 | R5: 0.03688 | S5: 0.03786 | T5: 0.03886 | U5: 0.03988 | V5: 0.04091 | W5: 0.04196 | X5: 0.04302 | Y5: 0.0441 | Z5: 0.04518 | AA5: 0.04628 | AB5: 0.04739 | AC5: 0.0485 | AD5: 0.04963 | AE5: 0.05076 | AF5: 0.0519 | AG5: 0.05306 | AH5: 0.05423 | AI5: 0.05541 | AJ5: 0.0566 | AK5: 0.05781 | AL5: 0.05903 | AM5: 0.06024 | AN5: 0.06144 | AO5: 0.06263 | AP5: 0.06378 | AQ5: 0.06491 | AR5: 0.06603 | AS5: 0.06623 | AT5: 0.06823 | AU5: 0.06932 | AV5: 0.07041 | AW5: 0.07147 | AX5: 0.07248 | AY5: 0.07342 | AZ5: 0.07428 | BA5: 0.07507 | BB5: 0.07579 | BC5: 0.07647 | BD5: 0.07714 | BF5: 0.02339 | BG5: 0.02399 | BH5: 0.0246 | BI5: 0.02523 | BJ5: 0.02589 | BK5: 0.02657 | BL5: 0.02727 | BM5: 0.02799 | BN5: 0.02873 | BO5: 0.02949 | BP5: 0.03026 | BQ5: 0.03106 | BR5: 0.03188 | BS5: 0.03272 | BT5: 0.03357 | BU5: 0.03445 | BV5: 0.03535 | BW5: 0.03628 | BX5: 0.03722 | BY5: 0.03817 | BZ5: 0.03914 | CA5: 0.04011 | CB5: 0.04108 | CC5: 0.04206 | CD5: 0.04305 | CE5: 0.04405 | CF5: 0.04506 | CG5: 0.0461 | CH5: 0.04715 | CI5: 0.04823 | CJ5: 0.04932 | CK5: 0.05044 | CL5: 0.05156 | CM5: 0.05271 | CN5: 0.05386 | CO5: 0.05502 | CP5: 0.05617 | CQ5: 0.05733 | CR5: 0.0585 | CS5: 0.05969 | CT5: 0.06092 | CU5: 0.0622 | CV5: 0.06352 | CW5: 0.06487 | CX5: 0.06624 | CY5: 0.06757 | CZ5: 0.06884 | DA5: 0.07004 | DB5: 0.07117 | DC5: 0.07227 | DD5: 0.07337 | DE5: 0.07453
A6: =A5*(1+Simulador!$G$3) -> 582.02902 | D6: 6 | E6: 0.05422 | F6: 0.05541 | G6: 0.05668 | H6: 0.05802 | I6: 0.05944 | J6: 0.06095 | K6: 0.06253 | L6: 0.06419 | M6: 0.06591 | N6: 0.06769 | O6: 0.06952 | P6: 0.07139 | Q6: 0.07331 | R6: 0.07526 | S6: 0.07724 | T6: 0.07927 | U6: 0.08133 | V6: 0.08342 | W6: 0.08555 | X6: 0.0877 | Y6: 0.08988 | Z6: 0.09209 | AA6: 0.09431 | AB6: 0.09656 | AC6: 0.09883 | AD6: 0.10112 | AE6: 0.10343 | AF6: 0.10577 | AG6: 0.10813 | AH6: 0.11051 | AI6: 0.11293 | AJ6: 0.11537 | AK6: 0.11783 | AL6: 0.1203 | AM6: 0.12276 | AN6: 0.12519 | AO6: 0.12758 | AP6: 0.12994 | AQ6: 0.13226 | AR6: 0.13456 | AS6: 0.13684 | AT6: 0.13911 | AU6: 0.14137 | AV6: 0.14087 | AW6: 0.14573 | AX6: 0.14777 | AY6: 0.14968 | AZ6: 0.15145 | BA6: 0.1531 | BB6: 0.15466 | BC6: 0.15615 | BD6: 0.15758 | BF6: 0.04769 | BG6: 0.04891 | BH6: 0.05016 | BI6: 0.05146 | BJ6: 0.05281 | BK6: 0.05419 | BL6: 0.05562 | BM6: 0.05709 | BN6: 0.0586 | BO6: 0.06014 | BP6: 0.06173 | BQ6: 0.06335 | BR6: 0.06502 | BS6: 0.06672 | BT6: 0.06847 | BU6: 0.07026 | BV6: 0.0721 | BW6: 0.07397 | BX6: 0.07588 | BY6: 0.07781 | BZ6: 0.07976 | CA6: 0.08172 | CB6: 0.0837 | CC6: 0.08569 | CD6: 0.08771 | CE6: 0.08975 | CF6: 0.09183 | CG6: 0.09395 | CH6: 0.09611 | CI6: 0.09831 | CJ6: 0.10055 | CK6: 0.10282 | CL6: 0.10512 | CM6: 0.10745 | CN6: 0.10979 | CO6: 0.11215 | CP6: 0.11451 | CQ6: 0.1169 | CR6: 0.11932 | CS6: 0.12179 | CT6: 0.12435 | CU6: 0.12698 | CV6: 0.13468 | CW6: 0.13241 | CX6: 0.13513 | CY6: 0.13777 | CZ6: 0.1403 | DA6: 0.14273 | DB6: 0.14507 | DC6: 0.14739 | DD6: 0.14975 | DE6: 0.15218
A7: =A6*(1+Simulador!$G$3) -> 614.04062 | D7: 7 | E7: 0.08064 | F7: 0.08248 | G7: 0.08442 | H7: 0.08646 | I7: 0.08862 | J7: 0.09089 | K7: 0.09326 | L7: 0.09573 | M7: 0.09829 | N7: 0.10092 | O7: 0.10363 | P7: 0.1064 | Q7: 0.10922 | R7: 0.11211 | S7: 0.11505 | T7: 0.11805 | U7: 0.1211 | V7: 0.1242 | W7: 0.12734 | X7: 0.13053 | Y7: 0.13376 | Z7: 0.13703 | AA7: 0.14033 | AB7: 0.14367 | AC7: 0.14705 | AD7: 0.15045 | AE7: 0.1539 | AF7: 0.15739 | AG7: 0.16091 | AH7: 0.16448 | AI7: 0.16808 | AJ7: 0.17172 | AK7: 0.17537 | AL7: 0.17903 | AM7: 0.18267 | AN7: 0.18628 | AO7: 0.18984 | AP7: 0.19337 | AQ7: 0.19686 | AR7: 0.20033 | AS7: 0.20379 | AT7: 0.20721 | AU7: 0.21059 | AV7: 0.2139 | AW7: 0.21709 | AX7: 0.22014 | AY7: 0.22303 | AZ7: 0.22576 | BA7: 0.22834 | BB7: 0.23081 | BC7: 0.23316 | BD7: 0.2354 | BF7: 0.07098 | BG7: 0.07281 | BH7: 0.07469 | BI7: 0.07664 | BJ7: 0.07864 | BK7: 0.08071 | BL7: 0.08283 | BM7: 0.08502 | BN7: 0.08726 | BO7: 0.08956 | BP7: 0.09192 | BQ7: 0.09434 | BR7: 0.09682 | BS7: 0.09936 | BT7: 0.10196 | BU7: 0.10462 | BV7: 0.10735 | BW7: 0.11012 | BX7: 0.11293 | BY7: 0.11578 | BZ7: 0.11867 | CA7: 0.12157 | CB7: 0.12451 | CC7: 0.12748 | CD7: 0.13049 | CE7: 0.13354 | CF7: 0.13665 | CG7: 0.13982 | CH7: 0.14305 | CI7: 0.14634 | CJ7: 0.14967 | CK7: 0.15306 | CL7: 0.15649 | CM7: 0.15995 | CN7: 0.16344 | CO7: 0.16695 | CP7: 0.1705 | CQ7: 0.1741 | CR7: 0.17776 | CS7: 0.18151 | CT7: 0.18537 | CU7: 0.18931 | CV7: 0.19331 | CW7: 0.19732 | CX7: 0.20127 | CY7: 0.20513 | CZ7: 0.20888 | DA7: 0.21252 | DB7: 0.21611 | DC7: 0.21971 | DD7: 0.22335 | DE7: 0.22703
A8: =A7*(1+Simulador!$G$3) -> 647.81285 | D8: 8 | E8: 0.11283 | F8: 0.11547 | G8: 0.11825 | H8: 0.12117 | I8: 0.12423 | J8: 0.12743 | K8: 0.13076 | L8: 0.13421 | M8: 0.13778 | N8: 0.14144 | O8: 0.1452 | P8: 0.14905 | Q8: 0.15298 | R8: 0.157 | S8: 0.16109 | T8: 0.16527 | U8: 0.16951 | V8: 0.17382 | W8: 0.17821 | X8: 0.18265 | Y8: 0.18716 | Z8: 0.19171 | AA8: 0.19633 | AB8: 0.20099 | AC8: 0.20572 | AD8: 0.2105 | AE8: 0.21533 | AF8: 0.22022 | AG8: 0.22518 | AH8: 0.23019 | AI8: 0.23525 | AJ8: 0.24033 | AK8: 0.24544 | AL8: 0.25054 | AM8: 0.25563 | AN8: 0.26068 | AO8: 0.2657 | AP8: 0.27069 | AQ8: 0.27565 | AR8: 0.28059 | AS8: 0.2855 | AT8: 0.29036 | AU8: 0.29514 | AV8: 0.2998 | AW8: 0.30432 | AX8: 0.30867 | AY8: 0.31285 | AZ8: 0.31685 | BA8: 0.3207 | BB8: 0.32439 | BC8: 0.3279 | BD8: 0.3312 | BF8: 0.09935 | BG8: 0.10192 | BH8: 0.10457 | BI8: 0.10731 | BJ8: 0.11011 | BK8: 0.11301 | BL8: 0.11599 | BM8: 0.11904 | BN8: 0.12218 | BO8: 0.1254 | BP8: 0.12869 | BQ8: 0.13208 | BR8: 0.13555 | BS8: 0.1391 | BT8: 0.14273 | BU8: 0.14645 | BV8: 0.15024 | BW8: 0.1541 | BX8: 0.15801 | BY8: 0.16198 | BZ8: 0.16599 | CA8: 0.17004 | CB8: 0.17415 | CC8: 0.17831 | CD8: 0.18254 | CE8: 0.18684 | CF8: 0.19122 | CG8: 0.19568 | CH8: 0.20021 | CI8: 0.20482 | CJ8: 0.2095 | CK8: 0.21425 | CL8: 0.21905 | CM8: 0.22389 | CN8: 0.22878 | CO8: 0.23373 | CP8: 0.23875 | CQ8: 0.24386 | CR8: 0.24908 | CS8: 0.25442 | CT8: 0.25986 | CU8: 0.26538 | CV8: 0.27093 | CW8: 0.27646 | CX8: 0.28191 | CY8: 0.28728 | CZ8: 0.29256 | DA8: 0.29779 | DB8: 0.303 | DC8: 0.30822 | DD8: 0.31345 | DE8: 0.31865
A9: =A8*(1+Simulador!$G$3) -> 683.44256 | D9: 9 | E9: 0.15105 | F9: 0.15468 | G9: 0.158245 | H9: 0.16244 | I9: 0.16658 | J9: 0.17088 | K9: 0.17534 | L9: 0.17995 | M9: 0.1847 | N9: 0.18958 | O9: 0.19458 | P9: 0.1997 | Q9: 0.20493 | R9: 0.21028 | S9: 0.21573 | T9: 0.22128 | U9: 0.2269 | V9: 0.2327 | W9: 0.23854 | X9: 0.24446 | Y9: 0.25047 | Z9: 0.25656 | AA9: 0.26273 | AB9: 0.26898 | AC9: 0.27532 | AD9: 0.28173 | AE9: 0.28822 | AF9: 0.2948 | AG9: 0.30146 | AH9: 0.30819 | AI9: 0.31497 | AJ9: 0.32178 | AK9: 0.32861 | AL9: 0.33545 | AM9: 0.34227 | AN9: 0.34908 | AO9: 0.35588 | AP9: 0.36266 | AQ9: 0.36942 | AR9: 0.37615 | AS9: 0.38283 | AT9: 0.38943 | AU9: 0.39593 | AV9: 0.40229 | AW9: 0.40849 | AX9: 0.41452 | AY9: 0.42038 | AZ9: 0.42607 | BA9: 0.43158 | BB9: 0.43688 | BC9: 0.44193 | BD9: 0.44666 | BF9: 0.13302 | BG9: 0.13648 | BH9: 0.14004 | BI9: 0.1437 | BJ9: 0.14747 | BK9: 0.15135 | BL9: 0.15533 | BM9: 0.15942 | BN9: 0.16362 | BO9: 0.16792 | BP9: 0.17234 | BQ9: 0.17687 | BR9: 0.1815 | BS9: 0.18625 | BT9: 0.19111 | BU9: 0.19607 | BV9: 0.20112 | BW9: 0.20625 | BX9: 0.21146 | BY9: 0.21674 | BZ9: 0.22209 | CA9: 0.22751 | CB9: 0.23301 | CC9: 0.2386 | CD9: 0.24429 | CE9: 0.25008 | CF9: 0.25596 | CG9: 0.26195 | CH9: 0.26804 | CI9: 0.27423 | CJ9: 0.28051 | CK9: 0.28687 | CL9: 0.2933 | CM9: 0.29981 | CN9: 0.30641 | CO9: 0.3131 | CP9: 0.31991 | CQ9: 0.32686 | CR9: 0.03335 | CS9: 0.34117 | CT9: 0.34849 | CU9: 0.35586 | CV9: 0.36323 | CW9: 0.37056 | CX9: 0.37785 | CY9: 0.38509 | CZ9: 0.39231 | DA9: 0.39952 | DB9: 0.40673 | DC9: 0.41393 | DD9: 0.42108 | DE9: 0.42809
A10: =A9*(1+Simulador!$G$3) -> 721.0319 | D10: 10 | E10: 0.19561 | F10: 0.2004 | G10: 0.20539 | H10: 0.21059 | I10: 0.21598 | J10: 0.22156 | K10: 0.22733 | L10: 0.23328 | M10: 0.23939 | N10: 0.24567 | O10: 0.2521 | P10: 0.25869 | Q10: 0.26543 | R10: 0.27232 | S10: 0.27934 | T10: 0.2865 | U10: 0.29379 | V10: 0.30121 | W10: 0.30874 | X10: 0.31639 | Y10: 0.32416 | Z10: 0.33203 | AA10: 0.34002 | AB10: 0.34813 | AC10: 0.35634 | AD10: 0.36468 | AE10: 0.37312 | AF10: 0.38168 | AG10: 0.39033 | AH10: 0.39906 | AI10: 0.40785 | AJ10: 0.41669 | AK10: 0.42556 | AL10: 0.43444 | AM10: 0.44334 | AN10: 0.45226 | AO10: 0.46119 | AP10: 0.37012 | AQ10: 0.47904 | AR10: 0.48793 | AS10: 0.49675 | AT10: 0.50548 | AU10: 0.51408 | AV10: 0.52256 | AW10: 0.5309 | AX10: 0.5391 | AY10: 0.54716 | AZ10: 0.55505 | BA10: 0.56274 | BB10: 0.57017 | BC10: 0.57728 | BD10: 0.58402 | BF10: 0.17222 | BG10: 0.17672 | BH10: 0.18134 | BI10: 0.18609 | BJ10: 0.19098 | BK10: 0.196 | BL10: 0.20115 | BM10: 0.20644 | BN10: 0.21187 | BO10: 0.21744 | BP10: 0.22316 | BQ10: 0.22901 | BR10: 0.23501 | BS10: 0.24115 | BT10: 0.24742 | BU10: 0.25381 | BV10: 0.26031 | BW10: 0.26691 | BX10: 0.27362 | BY10: 0.28043 | BZ10: 0.28734 | CA10: 0.29437 | CB10: 0.30151 | CC10: 0.30877 | CD10: 0.31617 | CE10: 0.3237 | CF10: 0.33135 | CG10: 0.33914 | CH10: 0.34705 | CI10: 0.35508 | CJ10: 0.36323 | CK10: 0.37148 | CL10: 0.37984 | CM10: 0.38832 | CN10: 0.39693 | CO10: 0.40571 | CP10: 0.41466 | CQ10: 0.42379 | CR10: 0.43307 | CS10: 0.44249 | CT10: 0.45197 | CU10: 0.46148 | CV10: 0.471 | CW10: 0.48052 | CX10: 0.49003 | CY10: 0.49958 | CZ10: 0.50918 | DA10: 0.51881 | DB10: 0.52845 | DC10: 0.53803 | DD10: 0.54747 | DE10: 0.5567
A11: =A10*(1+Simulador!$G$3) -> 760.68865 | D11: 11 | E11: 0.2598 | F11: 0.26627 | G11: 0.27299 | H11: 0.27994 | I11: 0.28712 | J11: 0.29453 | K11: 0.30216 | L11: 0.31002 | M11: 0.3181 | N11: 0.32638 | O11: 0.33487 | P11: 0.34357 | Q11: 0.35248 | R11: 0.36157 | S11: 0.37085 | T11: 0.38031 | U11: 0.38995 | V11: 0.39976 | W11: 0.40974 | X11: 0.41988 | Y11: 0.43018 | Z11: 0.43018 | AA11: 0.45126 | AB11: 0.46204 | AC11: 0.47299 | AD11: 0.4841 | AE11: 0.49536 | AF11: 0.50677 | AG11: 0.5183 | AH11: 0.52993 | AI11: 0.54165 | AJ11: 0.55343 | AK11: 0.56526 | AL11: 0.57716 | AM11: 0.58912 | AN11: 0.60114 | AO11: 0.6132 | AP11: 0.62531 | AQ11: 0.63741 | AR11: 0.64948 | AS11: 0.66148 | AT11: 0.6734 | AU11: 0.68522 | AV11: 0.69695 | AW11: 0.7086 | AX11: 0.72016 | AY11: 0.73162 | AZ11: 0.74293 | BA11: 0.75405 | BB11: 0.76489 | BC11: 0.77541 | BD11: 0.78557 | BF11: 0.22865 | BG11: 0.23462 | BH11: 0.24078 | BI11: 0.24709 | BJ11: 0.25358 | BK11: 0.26024 | BL11: 0.26708 | BM11: 0.2741 | BN11: 0.2813 | BO11: 0.2887 | BP11: 0.29627 | BQ11: 0.30404 | BR11: 0.31199 | BS11: 0.32012 | BT11: 0.3284 | BU11: 0.33684 | BV11: 0.34543 | BW11: 0.35416 | BX11: 0.36303 | BY11: 0.37205 | BZ11: 0.38123 | CA11: 0.39057 | CB11: 0.40008 | CC11: 0.40977 | CD11: 0.41963 | CE11: 0.42967 | CF11: 0.43987 | CG11: 0.45025 | CH11: 0.46079 | CI11: 0.47149 | CJ11: 0.48233 | CK11: 0.49333 | CL11: 0.50449 | CM11: 0.51585 | CN11: 0.52743 | CO11: 0.53924 | CP11: 0.55129 | CQ11: 0.56355 | CR11: 0.57599 | CS11: 0.58854 | CT11: 0.60116 | CU11: 0.61382 | CV11: 0.62653 | CW11: 0.6393 | CX11: 0.65217 | CY11: 0.66517 | CZ11: 0.6783 | DA11: 0.6915 | DB11: 0.70471 | DC11: 0.71782 | DD11: 0.73074 | DE11: 0.74341
D12: 12 | E12: 0.26627 | F12: 0.27299 | G12: 0.27994 | H12: 0.28712 | I12: 0.29453 | J12: 0.30216 | K12: 0.31002 | L12: 0.3181 | M12: 0.32638 | N12: 0.33487 | O12: 0.34357 | P12: 0.35248 | Q12: 0.36157 | R12: 0.37085 | S12: 0.38031 | T12: 0.38995 | U12: 0.39976 | V12: 0.40974 | W12: 0.41988 | X12: 0.43018 | Y12: 0.44064 | Z12: 0.45126 | AA12: 0.46204 | AB12: 0.47299 | AC12: 0.4841 | AD12: 0.49536 | AE12: 0.50677 | AF12: 0.5183 | AG12: 0.52993 | AH12: 0.54165 | AI12: 0.55343 | AJ12: 0.56526 | AK12: 0.57716 | AL12: 0.58912 | AM12: 0.60114 | AN12: 0.6132 | AO12: 0.62531 | AP12: 0.63741 | AQ12: 0.64948 | AR12: 0.66148 | AS12: 0.6734 | AT12: 0.68522 | AU12: 0.69695 | AV12: 0.7086 | AW12: 0.72016 | AX12: 0.73162 | AY12: 0.74293 | AZ12: 0.75405 | BA12: 0.76489 | BB12: 0.77541 | BC12: 0.78557 | BD12: 0.79538 | BF12: 0.23462 | BG12: 0.24078 | BH12: 0.24709 | BI12: 0.25358 | BJ12: 0.26024 | BK12: 0.26708 | BL12: 0.2741 | BM12: 0.2813 | BN12: 0.2887 | BO12: 0.29627 | BP12: 0.30404 | BQ12: 0.31199 | BR12: 0.32012 | BS12: 0.3284 | BT12: 0.33684 | BU12: 0.34543 | BV12: 0.35416 | BW12: 0.36303 | BX12: 0.37205 | BY12: 0.38123 | BZ12: 0.39057 | CA12: 0.40008 | CB12: 0.40977 | CC12: 0.41963 | CD12: 0.42967 | CE12: 0.43987 | CF12: 0.45025 | CG12: 0.46079 | CH12: 0.47149 | CI12: 0.48233 | CJ12: 0.49333 | CK12: 0.50449 | CL12: 0.51585 | CM12: 0.52743 | CN12: 0.53924 | CO12: 0.55129 | CP12: 0.56355 | CQ12: 0.57599 | CR12: 0.58854 | CS12: 0.60116 | CT12: 0.61382 | CU12: 0.62653 | CV12: 0.6393 | CW12: 0.65217 | CX12: 0.66517 | CY12: 0.6783 | CZ12: 0.6915 | DA12: 0.70471 | DB12: 0.71782 | DC12: 0.73074 | DD12: 0.74341 | DE12: 0.75581
D13: 13 | E13: 0.27299 | F13: 0.27994 | G13: 0.28712 | H13: 0.29453 | I13: 0.30216 | J13: 0.31002 | K13: 0.3181 | L13: 0.32638 | M13: 0.33487 | N13: 0.34357 | O13: 0.35248 | P13: 0.36157 | Q13: 0.37085 | R13: 0.38031 | S13: 0.38995 | T13: 0.39976 | U13: 0.40974 | V13: 0.41988 | W13: 0.43018 | X13: 0.44064 | Y13: 0.45126 | Z13: 0.46204 | AA13: 0.47299 | AB13: 0.4841 | AC13: 0.49536 | AD13: 0.50677 | AE13: 0.5183 | AF13: 0.52993 | AG13: 0.54165 | AH13: 0.55343 | AI13: 0.56526 | AJ13: 0.57716 | AK13: 0.58912 | AL13: 0.60114 | AM13: 0.6132 | AN13: 0.62531 | AO13: 0.63741 | AP13: 0.64948 | AQ13: 0.66148 | AR13: 0.6734 | AS13: 0.68522 | AT13: 0.69695 | AU13: 0.7086 | AV13: 0.72016 | AW13: 0.73162 | AX13: 0.74293 | AY13: 0.75405 | AZ13: 0.76489 | BA13: 0.77541 | BB13: 0.78557 | BC13: 0.79538 | BD13: 0.80486 | BF13: 0.24078 | BG13: 0.24709 | BH13: 0.25358 | BI13: 0.26024 | BJ13: 0.26708 | BK13: 0.2741 | BL13: 0.2813 | BM13: 0.2887 | BN13: 0.29627 | BO13: 0.30404 | BP13: 0.31199 | BQ13: 0.32012 | BR13: 0.3284 | BS13: 0.33684 | BT13: 0.34543 | BU13: 0.35416 | BV13: 0.36303 | BW13: 0.37205 | BX13: 0.38123 | BY13: 0.39057 | BZ13: 0.40008 | CA13: 0.40977 | CB13: 0.41963 | CC13: 0.42967 | CD13: 0.43987 | CE13: 0.45025 | CF13: 0.46079 | CG13: 0.47149 | CH13: 0.48233 | CI13: 0.49333 | CJ13: 0.50449 | CK13: 0.51585 | CL13: 0.52743 | CM13: 0.53924 | CN13: 0.55129 | CO13: 0.56355 | CP13: 0.57599 | CQ13: 0.58854 | CR13: 0.60116 | CS13: 0.61382 | CT13: 0.62653 | CU13: 0.6393 | CV13: 0.65217 | CW13: 0.66517 | CX13: 0.6783 | CY13: 0.6915 | CZ13: 0.70471 | DA13: 0.71782 | DB13: 0.73074 | DC13: 0.74341 | DD13: 0.75581 | DE13: 0.76794
D14: 14 | E14: 0.27994 | F14: 0.28712 | G14: 0.29453 | H14: 0.30216 | I14: 0.31002 | J14: 0.3181 | K14: 0.32638 | L14: 0.33487 | M14: 0.34357 | N14: 0.35248 | O14: 0.36157 | P14: 0.37085 | Q14: 0.38031 | R14: 0.38995 | S14: 0.39976 | T14: 0.40974 | U14: 0.41988 | V14: 0.43018 | W14: 0.44064 | X14: 0.45126 | Y14: 0.46204 | Z14: 0.47299 | AA14: 0.4841 | AB14: 0.49536 | AC14: 0.50677 | AD14: 0.5183 | AE14: 0.52993 | AF14: 0.54165 | AG14: 0.55343 | AH14: 0.56526 | AI14: 0.57716 | AJ14: 0.58912 | AK14: 0.60114 | AL14: 0.6132 | AM14: 0.62531 | AN14: 0.63741 | AO14: 0.64948 | AP14: 0.66148 | AQ14: 0.6734 | AR14: 0.68522 | AS14: 0.69695 | AT14: 0.7086 | AU14: 0.72016 | AV14: 0.73162 | AW14: 0.74293 | AX14: 0.75405 | AY14: 0.76489 | AZ14: 0.77541 | BA14: 0.78557 | BB14: 0.79538 | BC14: 0.80486 | BD14: 0.81406 | BF14: 0.24709 | BG14: 0.25358 | BH14: 0.26024 | BI14: 0.26708 | BJ14: 0.2741 | BK14: 0.2813 | BL14: 0.2887 | BM14: 0.29627 | BN14: 0.30404 | BO14: 0.31199 | BP14: 0.32012 | BQ14: 0.3284 | BR14: 0.33684 | BS14: 0.34543 | BT14: 0.35416 | BU14: 0.36303 | BV14: 0.37205 | BW14: 0.38123 | BX14: 0.39057 | BY14: 0.40008 | BZ14: 0.40977 | CA14: 0.41963 | CB14: 0.42967 | CC14: 0.43987 | CD14: 0.45025 | CE14: 0.46079 | CF14: 0.47149 | CG14: 0.48233 | CH14: 0.49333 | CI14: 0.50449 | CJ14: 0.51585 | CK14: 0.52743 | CL14: 0.53924 | CM14: 0.55129 | CN14: 0.56355 | CO14: 0.57599 | CP14: 0.58854 | CQ14: 0.60116 | CR14: 0.61382 | CS14: 0.62653 | CT14: 0.6393 | CU14: 0.65217 | CV14: 0.66517 | CW14: 0.6783 | CX14: 0.6915 | CY14: 0.70471 | CZ14: 0.71782 | DA14: 0.73074 | DB14: 0.74341 | DC14: 0.75581 | DD14: 0.76794 | DE14: 0.77981
D15: 15 | E15: 0.28712 | F15: 0.29453 | G15: 0.30216 | H15: 0.31002 | I15: 0.3181 | J15: 0.32638 | K15: 0.33487 | L15: 0.34357 | M15: 0.35248 | N15: 0.36157 | O15: 0.37085 | P15: 0.38031 | Q15: 0.38995 | R15: 0.39976 | S15: 0.40974 | T15: 0.41988 | U15: 0.43018 | V15: 0.44064 | W15: 0.45126 | X15: 0.46204 | Y15: 0.47299 | Z15: 0.4841 | AA15: 0.49536 | AB15: 0.50677 | AC15: 0.5183 | AD15: 0.52993 | AE15: 0.54165 | AF15: 0.55343 | AG15: 0.56526 | AH15: 0.57716 | AI15: 0.58912 | AJ15: 0.60114 | AK15: 0.6132 | AL15: 0.62531 | AM15: 0.63741 | AN15: 0.64948 | AO15: 0.66148 | AP15: 0.6734 | AQ15: 0.68522 | AR15: 0.69695 | AS15: 0.7086 | AT15: 0.72016 | AU15: 0.73162 | AV15: 0.74293 | AW15: 0.75405 | AX15: 0.76489 | AY15: 0.77541 | AZ15: 0.78557 | BA15: 0.79538 | BB15: 0.80486 | BC15: 0.81406 | BD15: 0.82303 | BF15: 0.25358 | BG15: 0.26024 | BH15: 0.26708 | BI15: 0.2741 | BJ15: 0.2813 | BK15: 0.2887 | BL15: 0.29627 | BM15: 0.30404 | BN15: 0.31199 | BO15: 0.32012 | BP15: 0.3284 | BQ15: 0.33684 | BR15: 0.34543 | BS15: 0.35416 | BT15: 0.36303 | BU15: 0.37205 | BV15: 0.38123 | BW15: 0.39057 | BX15: 0.40008 | BY15: 0.40977 | BZ15: 0.41963 | CA15: 0.42967 | CB15: 0.43987 | CC15: 0.45025 | CD15: 0.46079 | CE15: 0.47149 | CF15: 0.48233 | CG15: 0.49333 | CH15: 0.50449 | CI15: 0.51585 | CJ15: 0.52743 | CK15: 0.53924 | CL15: 0.55129 | CM15: 0.56355 | CN15: 0.57599 | CO15: 0.58854 | CP15: 0.60116 | CQ15: 0.61382 | CR15: 0.62653 | CS15: 0.6393 | CT15: 0.65217 | CU15: 0.66517 | CV15: 0.6783 | CW15: 0.6915 | CX15: 0.70471 | CY15: 0.71782 | CZ15: 0.73074 | DA15: 0.74341 | DB15: 0.75581 | DC15: 0.76794 | DD15: 0.77981 | DE15: 0.79146
D16: 16 | E16: 0.29453 | F16: 0.30216 | G16: 0.31002 | H16: 0.3181 | I16: 0.32638 | J16: 0.33487 | K16: 0.34357 | L16: 0.35248 | M16: 0.36157 | N16: 0.37085 | O16: 0.38031 | P16: 0.38995 | Q16: 0.39976 | R16: 0.40974 | S16: 0.41988 | T16: 0.43018 | U16: 0.44064 | V16: 0.45126 | W16: 0.46204 | X16: 0.47299 | Y16: 0.4841 | Z16: 0.49536 | AA16: 0.50677 | AB16: 0.5183 | AC16: 0.52993 | AD16: 0.54165 | AE16: 0.55343 | AF16: 0.56526 | AG16: 0.57716 | AH16: 0.58912 | AI16: 0.60114 | AJ16: 0.6132 | AK16: 0.62531 | AL16: 0.63741 | AM16: 0.64948 | AN16: 0.66148 | AO16: 0.6734 | AP16: 0.68522 | AQ16: 0.69695 | AR16: 0.7086 | AS16: 0.72016 | AT16: 0.73162 | AU16: 0.74293 | AV16: 0.75405 | AW16: 0.76489 | AX16: 0.77541 | AY16: 0.78557 | AZ16: 0.79538 | BA16: 0.80486 | BB16: 0.81406 | BC16: 0.82303 | BD16: 0.83178 | BF16: 0.26024 | BG16: 0.26708 | BH16: 0.2741 | BI16: 0.2813 | BJ16: 0.2887 | BK16: 0.29627 | BL16: 0.30404 | BM16: 0.31199 | BN16: 0.32012 | BO16: 0.3284 | BP16: 0.33684 | BQ16: 0.34543 | BR16: 0.35416 | BS16: 0.36303 | BT16: 0.37205 | BU16: 0.38123 | BV16: 0.39057 | BW16: 0.40008 | BX16: 0.40977 | BY16: 0.41963 | BZ16: 0.42967 | CA16: 0.43987 | CB16: 0.45025 | CC16: 0.46079 | CD16: 0.47149 | CE16: 0.48233 | CF16: 0.49333 | CG16: 0.50449 | CH16: 0.51585 | CI16: 0.52743 | CJ16: 0.53924 | CK16: 0.55129 | CL16: 0.56355 | CM16: 0.57599 | CN16: 0.58854 | CO16: 0.60116 | CP16: 0.61382 | CQ16: 0.62653 | CR16: 0.6393 | CS16: 0.65217 | CT16: 0.66517 | CU16: 0.6783 | CV16: 0.6915 | CW16: 0.70471 | CX16: 0.71782 | CY16: 0.73074 | CZ16: 0.74341 | DA16: 0.75581 | DB16: 0.76794 | DC16: 0.77981 | DD16: 0.79146 | DE16: 0.80287
D17: 17 | E17: 0.30216 | F17: 0.31002 | G17: 0.3181 | H17: 0.32638 | I17: 0.33487 | J17: 0.34357 | K17: 0.35248 | L17: 0.36157 | M17: 0.37085 | N17: 0.38031 | O17: 0.38995 | P17: 0.39976 | Q17: 0.40974 | R17: 0.41988 | S17: 0.43018 | T17: 0.44064 | U17: 0.45126 | V17: 0.46204 | W17: 0.47299 | X17: 0.4841 | Y17: 0.49536 | Z17: 0.50677 | AA17: 0.5183 | AB17: 0.52993 | AC17: 0.54165 | AD17: 0.55343 | AE17: 0.56526 | AF17: 0.57716 | AG17: 0.58912 | AH17: 0.60114 | AI17: 0.6132 | AJ17: 0.62531 | AK17: 0.63741 | AL17: 0.64948 | AM17: 0.66148 | AN17: 0.6734 | AO17: 0.68522 | AP17: 0.69695 | AQ17: 0.7086 | AR17: 0.72016 | AS17: 0.73162 | AT17: 0.74293 | AU17: 0.75405 | AV17: 0.76489 | AW17: 0.77541 | AX17: 0.78557 | AY17: 0.79538 | AZ17: 0.80486 | BA17: 0.81406 | BB17: 0.82303 | BC17: 0.83178 | BD17: 0.84029 | BF17: 0.26708 | BG17: 0.2741 | BH17: 0.2813 | BI17: 0.2887 | BJ17: 0.29627 | BK17: 0.30404 | BL17: 0.31199 | BM17: 0.32012 | BN17: 0.3284 | BO17: 0.33684 | BP17: 0.34543 | BQ17: 0.35416 | BR17: 0.36303 | BS17: 0.37205 | BT17: 0.38123 | BU17: 0.39057 | BV17: 0.40008 | BW17: 0.40977 | BX17: 0.41963 | BY17: 0.42967 | BZ17: 0.43987 | CA17: 0.45025 | CB17: 0.46079 | CC17: 0.47149 | CD17: 0.48233 | CE17: 0.49333 | CF17: 0.50449 | CG17: 0.51585 | CH17: 0.52743 | CI17: 0.53924 | CJ17: 0.55129 | CK17: 0.56355 | CL17: 0.57599 | CM17: 0.58854 | CN17: 0.60116 | CO17: 0.61382 | CP17: 0.62653 | CQ17: 0.6393 | CR17: 0.65217 | CS17: 0.66517 | CT17: 0.6783 | CU17: 0.6915 | CV17: 0.70471 | CW17: 0.71782 | CX17: 0.73074 | CY17: 0.74341 | CZ17: 0.75581 | DA17: 0.76794 | DB17: 0.77981 | DC17: 0.79146 | DD17: 0.80287 | DE17: 0.814
D18: 18 | E18: 0.31002 | F18: 0.3181 | G18: 0.32638 | H18: 0.33487 | I18: 0.34357 | J18: 0.35248 | K18: 0.36157 | L18: 0.37085 | M18: 0.38031 | N18: 0.38995 | O18: 0.39976 | P18: 0.40974 | Q18: 0.41988 | R18: 0.43018 | S18: 0.44064 | T18: 0.45126 | U18: 0.46204 | V18: 0.47299 | W18: 0.4841 | X18: 0.49536 | Y18: 0.50677 | Z18: 0.5183 | AA18: 0.52993 | AB18: 0.54165 | AC18: 0.55343 | AD18: 0.56526 | AE18: 0.57716 | AF18: 0.58912 | AG18: 0.60114 | AH18: 0.6132 | AI18: 0.62531 | AJ18: 0.63741 | AK18: 0.64948 | AL18: 0.66148 | AM18: 0.6734 | AN18: 0.68522 | AO18: 0.69695 | AP18: 0.7086 | AQ18: 0.72016 | AR18: 0.73162 | AS18: 0.74293 | AT18: 0.75405 | AU18: 0.76489 | AV18: 0.77541 | AW18: 0.78557 | AX18: 0.79538 | AY18: 0.80486 | AZ18: 0.81406 | BA18: 0.82303 | BB18: 0.83178 | BC18: 0.84029 | BD18: 0.84852 | BF18: 0.2741 | BG18: 0.2813 | BH18: 0.2887 | BI18: 0.29627 | BJ18: 0.30404 | BK18: 0.31199 | BL18: 0.32012 | BM18: 0.3284 | BN18: 0.33684 | BO18: 0.34543 | BP18: 0.35416 | BQ18: 0.36303 | BR18: 0.37205 | BS18: 0.38123 | BT18: 0.39057 | BU18: 0.40008 | BV18: 0.40977 | BW18: 0.41963 | BX18: 0.42967 | BY18: 0.43987 | BZ18: 0.45025 | CA18: 0.46079 | CB18: 0.47149 | CC18: 0.48233 | CD18: 0.49333 | CE18: 0.50449 | CF18: 0.51585 | CG18: 0.52743 | CH18: 0.53924 | CI18: 0.55129 | CJ18: 0.56355 | CK18: 0.57599 | CL18: 0.58854 | CM18: 0.60116 | CN18: 0.61382 | CO18: 0.62653 | CP18: 0.6393 | CQ18: 0.65217 | CR18: 0.66517 | CS18: 0.6783 | CT18: 0.6915 | CU18: 0.70471 | CV18: 0.71782 | CW18: 0.73074 | CX18: 0.74341 | CY18: 0.75581 | CZ18: 0.76794 | DA18: 0.77981 | DB18: 0.79146 | DC18: 0.80287 | DD18: 0.814 | DE18: 0.82478
D19: 19 | E19: 0.3181 | F19: 0.32638 | G19: 0.33487 | H19: 0.34357 | I19: 0.35248 | J19: 0.36157 | K19: 0.37085 | L19: 0.38031 | M19: 0.38995 | N19: 0.39976 | O19: 0.40974 | P19: 0.41988 | Q19: 0.43018 | R19: 0.44064 | S19: 0.45126 | T19: 0.46204 | U19: 0.47299 | V19: 0.4841 | W19: 0.49536 | X19: 0.50677 | Y19: 0.5183 | Z19: 0.52993 | AA19: 0.54165 | AB19: 0.55343 | AC19: 0.56526 | AD19: 0.57716 | AE19: 0.58912 | AF19: 0.60114 | AG19: 0.6132 | AH19: 0.62531 | AI19: 0.63741 | AJ19: 0.64948 | AK19: 0.66148 | AL19: 0.6734 | AM19: 0.68522 | AN19: 0.69695 | AO19: 0.7086 | AP19: 0.72016 | AQ19: 0.73162 | AR19: 0.74293 | AS19: 0.75405 | AT19: 0.76489 | AU19: 0.77541 | AV19: 0.78557 | AW19: 0.79538 | AX19: 0.80486 | AY19: 0.81406 | AZ19: 0.82303 | BA19: 0.83178 | BB19: 0.84029 | BC19: 0.84852 | BD19: 0.8564 | BF19: 0.2813 | BG19: 0.2887 | BH19: 0.29627 | BI19: 0.30404 | BJ19: 0.31199 | BK19: 0.32012 | BL19: 0.3284 | BM19: 0.33684 | BN19: 0.34543 | BO19: 0.35416 | BP19: 0.36303 | BQ19: 0.37205 | BR19: 0.38123 | BS19: 0.39057 | BT19: 0.40008 | BU19: 0.40977 | BV19: 0.41963 | BW19: 0.42967 | BX19: 0.43987 | BY19: 0.45025 | BZ19: 0.46079 | CA19: 0.47149 | CB19: 0.48233 | CC19: 0.49333 | CD19: 0.50449 | CE19: 0.51585 | CF19: 0.52743 | CG19: 0.53924 | CH19: 0.55129 | CI19: 0.56355 | CJ19: 0.57599 | CK19: 0.58854 | CL19: 0.60116 | CM19: 0.61382 | CN19: 0.62653 | CO19: 0.6393 | CP19: 0.65217 | CQ19: 0.66517 | CR19: 0.6783 | CS19: 0.6915 | CT19: 0.70471 | CU19: 0.71782 | CV19: 0.73074 | CW19: 0.74341 | CX19: 0.75581 | CY19: 0.76794 | CZ19: 0.77981 | DA19: 0.79146 | DB19: 0.80287 | DC19: 0.814 | DD19: 0.82478 | DE19: 0.83514
D20: 20 | E20: 0.32638 | F20: 0.33487 | G20: 0.34357 | H20: 0.35248 | I20: 0.36157 | J20: 0.37085 | K20: 0.38031 | L20: 0.38995 | M20: 0.39976 | N20: 0.40974 | O20: 0.41988 | P20: 0.43018 | Q20: 0.44064 | R20: 0.45126 | S20: 0.46204 | T20: 0.47299 | U20: 0.4841 | V20: 0.49536 | W20: 0.50677 | X20: 0.5183 | Y20: 0.52993 | Z20: 0.54165 | AA20: 0.55343 | AB20: 0.56526 | AC20: 0.57716 | AD20: 0.58912 | AE20: 0.60114 | AF20: 0.6132 | AG20: 0.62531 | AH20: 0.63741 | AI20: 0.64948 | AJ20: 0.66148 | AK20: 0.6734 | AL20: 0.68522 | AM20: 0.69695 | AN20: 0.7086 | AO20: 0.72016 | AP20: 0.73162 | AQ20: 0.74293 | AR20: 0.75405 | AS20: 0.76489 | AT20: 0.77541 | AU20: 0.78557 | AV20: 0.79538 | AW20: 0.80486 | AX20: 0.81406 | AY20: 0.82303 | AZ20: 0.83178 | BA20: 0.84029 | BB20: 0.84852 | BC20: 0.8564 | BD20: 0.86387 | BF20: 0.2887 | BG20: 0.29627 | BH20: 0.30404 | BI20: 0.31199 | BJ20: 0.32012 | BK20: 0.3284 | BL20: 0.33684 | BM20: 0.34543 | BN20: 0.35416 | BO20: 0.36303 | BP20: 0.37205 | BQ20: 0.38123 | BR20: 0.39057 | BS20: 0.40008 | BT20: 0.40977 | BU20: 0.41963 | BV20: 0.42967 | BW20: 0.43987 | BX20: 0.45025 | BY20: 0.46079 | BZ20: 0.47149 | CA20: 0.48233 | CB20: 0.49333 | CC20: 0.50449 | CD20: 0.51585 | CE20: 0.52743 | CF20: 0.53924 | CG20: 0.55129 | CH20: 0.56355 | CI20: 0.57599 | CJ20: 0.58854 | CK20: 0.60116 | CL20: 0.61382 | CM20: 0.62653 | CN20: 0.6393 | CO20: 0.65217 | CP20: 0.66517 | CQ20: 0.6783 | CR20: 0.6915 | CS20: 0.70471 | CT20: 0.71782 | CU20: 0.73074 | CV20: 0.74341 | CW20: 0.75581 | CX20: 0.76794 | CY20: 0.77981 | CZ20: 0.79146 | DA20: 0.80287 | DB20: 0.814 | DC20: 0.82478 | DD20: 0.83514 | DE20: 0.84503
